Workbook

Sheet Weighted_avg_p1_p9
C1: Layer | N1: conversion factors
A2: Parameter | B2: unit | C2: 7 | D2: 7-20 | E2: 20-47 | F2: 47-65 | G2: 65-85 | H2: 85-110 | I2: 110-130 | J2: 130-150 | K2: 150-175 | N2: g cm^3 to kg/dm^3 | O2: 1
A3: depth, mm | C3: 180 | D3: =(41-18)*10 -> 230 | E3: =(74-14)*10 -> 600 | F3: =(150-74)*10 -> 760 | G3: =(85-65)*10 -> 200 | H3: =(110-85)*10 -> 250
A4: depth, cm | C4: =C3/10 -> 18 | D4: =D3/10 -> 23 | E4: =E3/10 -> 60 | F4: =F3/10 -> 76 | G4: =G3/10 -> 20 | H4: =H3/10 -> 25
A6: ph | B6: - | C6: =SUM(Soils_Vertis_p9!C6*$D$30,Soils_Plonos_p1!C6*$D$31) -> 6.83 | D6: =SUM(Soils_Vertis_p9!D6*$D$30,Soils_Plonos_p1!D6*$D$31) -> 6.02 | E6: =SUM(Soils_Vertis_p9!E6*$D$30,Soils_Plonos_p1!E6*$D$31) -> 6.25 | F6: =SUM(Soils_Vertis_p9!F6*$D$30,Soils_Plonos_p1!F6*$D$31) -> 6.22 | G6: =SUM(Soils_Vertis_p9!G6*$D$30,Soils_Plonos_p1!G6*$D$31) -> 0 | H6: =SUM(Soils_Vertis_p9!H6*$D$30,Soils_Plonos_p1!H6*$D$31) -> 0 | N6: second to minute | O6: 60
A7: bd | B7: kg/dm^3 | C7: =SUM(Soils_Vertis_p9!C7*$D$30,Soils_Plonos_p1!C7*$D$31) -> 1.4675 | D7: =SUM(Soils_Vertis_p9!D7*$D$30,Soils_Plonos_p1!D7*$D$31) -> 1.4725 | E7: =SUM(Soils_Vertis_p9!E7*$D$30,Soils_Plonos_p1!E7*$D$31) -> 1.0575 | F7: =SUM(Soils_Vertis_p9!F7*$D$30,Soils_Plonos_p1!F7*$D$31) -> 0.0565 | G7: =SUM(Soils_Vertis_p9!G7*$D$30,Soils_Plonos_p1!G7*$D$31) -> 0 | H7: =SUM(Soils_Vertis_p9!H7*$D$30,Soils_Plonos_p1!H7*$D$31) -> 0
A9: clay | B9: kg/kg | C9: =SUM(Soils_Vertis_p9!C9*$D$30,Soils_Plonos_p1!C9*$D$31) -> 0.510225 | D9: =SUM(Soils_Vertis_p9!D9*$D$30,Soils_Plonos_p1!D9*$D$31) -> 0.228175 | E9: =SUM(Soils_Vertis_p9!E9*$D$30,Soils_Plonos_p1!E9*$D$31) -> 0.410715 | F9: =SUM(Soils_Vertis_p9!F9*$D$30,Soils_Plonos_p1!F9*$D$31) -> 0.27772 | G9: =SUM(Soils_Vertis_p9!G9*$D$30,Soils_Plonos_p1!G9*$D$31) -> 0 | H9: =SUM(Soils_Vertis_p9!H9*$D$30,Soils_Plonos_p1!H9*$D$31) -> 0
A10: sand | B10: kg/kg | C10: =SUM(Soils_Vertis_p9!C10*$D$30,Soils_Plonos_p1!C10*$D$31) -> 0.358 | D10: =SUM(Soils_Vertis_p9!D10*$D$30,Soils_Plonos_p1!D10*$D$31) -> 0.6472 | E10: =SUM(Soils_Vertis_p9!E10*$D$30,Soils_Plonos_p1!E10*$D$31) -> 0.53234 | F10: =SUM(Soils_Vertis_p9!F10*$D$30,Soils_Plonos_p1!F10*$D$31) -> 0.43729 | G10: =SUM(Soils_Vertis_p9!G10*$D$30,Soils_Plonos_p1!G10*$D$31) -> 0 | H10: =SUM(Soils_Vertis_p9!H10*$D$30,Soils_Plonos_p1!H10*$D$31) -> 0
A11: silt | B11: kg/kg | C11: =SUM(Soils_Vertis_p9!C11*$D$30,Soils_Plonos_p1!C11*$D$31) -> 0.12986 | D11: =SUM(Soils_Vertis_p9!D11*$D$30,Soils_Plonos_p1!D11*$D$31) -> 0.12035 | E11: =SUM(Soils_Vertis_p9!E11*$D$30,Soils_Plonos_p1!E11*$D$31) -> 0.04336 | F11: =SUM(Soils_Vertis_p9!F11*$D$30,Soils_Plonos_p1!F11*$D$31) -> 0.15636 | G11: =SUM(Soils_Vertis_p9!G11*$D$30,Soils_Plonos_p1!G11*$D$31) -> 0 | H11: =SUM(Soils_Vertis_p9!H11*$D$30,Soils_Plonos_p1!H11*$D$31) -> 0
A13: ksat | B13: cm/min | C13: =SUM(Soils_Vertis_p9!C13*$D$30,Soils_Plonos_p1!C13*$D$31) -> 0.345 | D13: =SUM(Soils_Vertis_p9!D13*$D$30,Soils_Plonos_p1!D13*$D$31) -> 0.108925 | E13: =SUM(Soils_Vertis_p9!E13*$D$30,Soils_Plonos_p1!E13*$D$31) -> 0.083865 | F13: =SUM(Soils_Vertis_p9!F13*$D$30,Soils_Plonos_p1!F13*$D$31) -> 0.1031 | G13: =SUM(Soils_Vertis_p9!G13*$D$30,Soils_Plonos_p1!G13*$D$31) -> 0 | H13: =SUM(Soils_Vertis_p9!H13*$D$30,Soils_Plonos_p1!H13*$D$31) -> 0
A14: wcmax | B14: dm^3/m^3 | C14: =SUM(Soils_Vertis_p9!C14*$D$30,Soils_Plonos_p1!C14*$D$31) -> 416.64 | D14: =SUM(Soils_Vertis_p9!D14*$D$30,Soils_Plonos_p1!D14*$D$31) -> 308.8 | E14: =SUM(Soils_Vertis_p9!E14*$D$30,Soils_Plonos_p1!E14*$D$31) -> 379.88 | F14: =SUM(Soils_Vertis_p9!F14*$D$30,Soils_Plonos_p1!F14*$D$31) -> 59.455 | G14: =SUM(Soils_Vertis_p9!G14*$D$30,Soils_Plonos_p1!G14*$D$31) -> 41.73 | H14: =SUM(Soils_Vertis_p9!H14*$D$30,Soils_Plonos_p1!H14*$D$31) -> 41.93
A15: wcmin | B15: dm^3/m^3 | C15: =SUM(Soils_Vertis_p9!C15*$D$30,Soils_Plonos_p1!C15*$D$31) -> 312.46 | D15: =SUM(Soils_Vertis_p9!D15*$D$30,Soils_Plonos_p1!D15*$D$31) -> 206.38 | E15: =SUM(Soils_Vertis_p9!E15*$D$30,Soils_Plonos_p1!E15*$D$31) -> 320.295 | F15: =SUM(Soils_Vertis_p9!F15*$D$30,Soils_Plonos_p1!F15*$D$31) -> 323.345 | G15: =SUM(Soils_Vertis_p9!G15*$D$30,Soils_Plonos_p1!G15*$D$31) -> 35.77 | H15: =SUM(Soils_Vertis_p9!H15*$D$30,Soils_Plonos_p1!H15*$D$31) -> 38.77
A17: corg | B17: kg/kg | C17: 0.0259 | D17: 0.0167 | E17: 0.0104 | F17: 0.0104
A18: norg
B24: Sources | C24: Gachene et al. (2024)
C25: ISRIC
C27: Missing data
B30: Weights | C30: Vertis p9 | D30: 0.05
C31: Planos p1 | D31: =1-D30 -> 0.95

Sheet Soils_Vertis_p9
C1: Layer | N1: conversion factors
A2: Parameter | B2: unit | C2: 7 | D2: 7-20 | E2: 20-47 | F2: 47-65 | G2: 65-85 | H2: 85-110 | I2: 110-130 | J2: 130-150 | K2: 150-175 | N2: g cm^3 to kg/dm^3 | O2: 1
A3: depth, mm | C3: 180 | D3: =(41-18)*10 -> 230 | E3: =(74-14)*10 -> 600 | F3: =(150-74)*10 -> 760 | G3: =(85-65)*10 -> 200 | H3: =(110-85)*10 -> 250
A4: depth, cm | C4: =C3/10 -> 18 | D4: =D3/10 -> 23 | E4: =E3/10 -> 60 | F4: =F3/10 -> 76 | G4: =G3/10 -> 20 | H4: =H3/10 -> 25
A6: ph | B6: - | C6: 6.83 | D6: 6.02 | E6: 6.25 | F6: 6.22 | N6: second to minute | O6: 60
A7: bd | B7: kg/dm^3 | C7: 0.85 | D7: 0.95 | E7: 1.01 | F7: 1.13
A9: clay | B9: kg/kg | C9: 0.5145 | D9: 0.5735 | E9: 0.6143 | F9: 0.6144
A10: sand | B10: kg/kg | C10: 0.358 | D10: 0.2995 | E10: 0.2785 | F10: 0.2984
A11: silt | B11: kg/kg | C11: 0.1272 | D11: 0.127 | E11: 0.1072 | F11: 0.0872
A13: ksat | B13: cm/min | C13: 0.25 | D13: 0.25 | E13: 0.41 | F13: 0.2
A14: wcmax | B14: dm^3/m^3 | C14: 411.7 | D14: 479.8 | E14: 632.2 | F14: 442.4 | G14: 41.73 | H14: 41.93
A15: wcmin | B15: dm^3/m^3 | C15: 319.3 | D15: 407.4 | E15: 512.1 | F15: 390.7 | G15: =35.77 -> 35.77 | H15: 38.77
A17: corg | B17: kg/kg | C17: 0.0259 | D17: 0.0167 | E17: 0.0104 | F17: 0.0104
A18: norg
B24: Sources | C24: Gachene et al. (2024)
C25: ISRIC
C27: Missing data

Sheet Soils_Plonos_p1
C1: Layer | N1: conversion factors
A2: Parameter | B2: unit | C2: 7 | D2: 7-20 | E2: 20-47 | F2: 47-65 | G2: 65-85 | H2: 85-110 | I2: 110-130 | J2: 130-150 | K2: 150-175 | N2: g cm^3 to kg/dm^3 | O2: 1
A3: depth, mm | C3: 180 | D3: =(41-18)*10 -> 230 | E3: =(74-14)*10 -> 600 | F3: =(150-74)*10 -> 760 | G3: =(85-65)*10 -> 200 | H3: =(110-85)*10 -> 250
A4: depth, cm | C4: =C3/10 -> 18 | D4: =D3/10 -> 23 | E4: =E3/10 -> 60 | F4: =F3/10 -> 76 | G4: =G3/10 -> 20 | H4: =H3/10 -> 25
A6: ph | B6: - | C6: 6.83 | D6: 6.02 | E6: 6.25 | F6: 6.22 | N6: second to minute | O6: 60
A7: bd | B7: kg/dm^3 | C7: 1.5 | D7: 1.5 | E7: 1.06
A9: clay | B9: kg/kg | C9: 0.51 | D9: 0.21 | E9: 0.4 | F9: 0.26
A10: sand | B10: kg/kg | C10: 0.358 | D10: 0.6655 | E10: 0.5457 | F10: 0.4446
A11: silt | B11: kg/kg | C11: 0.13 | D11: 0.12 | E11: 0.04 | F11: 0.16
A13: ksat | B13: cm/min | C13: 0.35 | D13: 0.1015 | E13: 0.0667 | F13: 0.098
A14: wcmax | B14: dm^3/m^3 | C14: 416.9 | D14: 299.8 | E14: 366.6 | F14: 39.3 | G14: 41.73 | H14: 41.93
A15: wcmin | B15: dm^3/m^3 | C15: 312.1 | D15: 195.8 | E15: 310.2 | F15: 319.8 | G15: =35.77 -> 35.77 | H15: 38.77
A17: corg | B17: kg/kg | C17: 0.0259 | D17: 0.0167 | E17: 0.0104 | F17: 0.0104
A18: norg
B24: Sources | C24: Gachene et al. (2024)
C25: ISRIC
C27: Missing data

Sheet Soil_parameters_Ferral_P8
C1: Layer | N1: conversion factors
A2: Parameter | B2: unit | C2: 7 | D2: 7-20 | E2: 20-47 | F2: 47-65 | G2: 65-85 | H2: 85-110 | I2: 110-130 | J2: 130-150 | K2: 150-175 | N2: g cm^3 to kg/dm^3 | O2: 1
A3: depth, mm | C3: 180 | D3: =(41-18)*10 -> 230 | E3: =(74-14)*10 -> 600 | F3: =(150-74)*10 -> 760 | G3: =(85-65)*10 -> 200 | H3: =(110-85)*10 -> 250
A4: depth, cm | C4: =C3/10 -> 18 | D4: =D3/10 -> 23 | E4: =E3/10 -> 60 | F4: =F3/10 -> 76 | G4: =G3/10 -> 20 | H4: =H3/10 -> 25
A6: ph | B6: - | C6: 6.83 | D6: 6.02 | E6: 6.25 | F6: 6.22 | N6: second to minute | O6: 60
A7: bd | B7: kg/dm^3 | C7: 1.14 | D7: 1.46 | E7: 1.57 | F7: 1.52
A9: clay | B9: kg/kg | C9: 0.0959 | D9: 0.0955 | E9: 0.096 | F9: 0.116
A10: sand | B10: kg/kg | C10: 0.8641 | D10: 0.85 | E10: 0.86 | F10: 0.82
A11: silt | B11: kg/kg | C11: 0.04 | D11: 0.06 | E11: 0.04 | F11: 0.04
A13: ksat | B13: cm/min | C13: 0.35 | D13: 0.1015 | E13: 0.0667 | F13: 0.098
A14: wcmax | B14: dm^3/m^3 | C14: =225.6 -> 225.6 | D14: =297.5 -> 297.5 | E14: =348.6 -> 348.6 | F14: =434.5 -> 434.5 | G14: 41.73 | H14: 41.93
A15: wcmin | B15: dm^3/m^3 | C15: =39.4 -> 39.4 | D15: =105.8 -> 105.8 | E15: =98.9 -> 98.9 | F15: =158.5 -> 158.5 | G15: =35.77 -> 35.77 | H15: 38.77
A17: corg | B17: kg/kg | C17: 0.0259 | D17: 0.0167 | E17: 0.0104 | F17: 0.0104
A18: norg
B24: Sources | C24: Gachene et al. (2024)
C25: ISRIC
C27: Missing data

Sheet Soils_Vertis_p4
C1: Layer | N1: conversion factors
A2: Parameter | B2: unit | C2: 7 | D2: 7-20 | E2: 20-47 | F2: 47-65 | G2: 65-85 | H2: 85-110 | I2: 110-130 | J2: 130-150 | K2: 150-175 | N2: g cm^3 to kg/dm^3 | O2: 1
A3: depth, mm | C3: 180 | D3: =(41-18)*10 -> 230 | E3: =(74-14)*10 -> 600 | F3: =(150-74)*10 -> 760 | G3: =(85-65)*10 -> 200 | H3: =(110-85)*10 -> 250
A4: depth, cm | C4: =C3/10 -> 18 | D4: =D3/10 -> 23 | E4: =E3/10 -> 60 | F4: =F3/10 -> 76 | G4: =G3/10 -> 20 | H4: =H3/10 -> 25
A6: ph | B6: - | C6: 6.83 | D6: 6.02 | E6: 6.25 | F6: 6.22 | N6: second to minute | O6: 60
A7: bd | B7: kg/dm^3 | C7: 1.1 | D7: 1.2 | E7: 1.32 | F7: 1.24
A9: clay | B9: kg/kg | C9: 0.6 | D9: 0.6 | E9: 0.6 | F9: 0.6
A10: sand | B10: kg/kg | C10: 0.3 | D10: 0.3 | E10: 0.3 | F10: 0.3
A11: silt | B11: kg/kg | C11: 0.1 | D11: 0.1 | E11: 0.1 | F11: 0.1
A13: ksat | B13: cm/min | C13: =Soils_Vertis_p7!C13 -> 0.25 | D13: =Soils_Vertis_p7!D13 -> 0.25 | E13: =Soils_Vertis_p7!E13 -> 0.41 | F13: =Soils_Vertis_p7!F13 -> 0.2
A14: wcmax | B14: dm^3/m^3 | C14: 420.6 | D14: 562.9 | E14: 416.7 | F14: 442.4 | G14: 41.73 | H14: 41.93
A15: wcmin | B15: dm^3/m^3 | C15: 356.6 | D15: 434 | E15: 300.6 | F15: 390.7 | G15: =35.77 -> 35.77 | H15: 38.77
A17: corg | B17: kg/kg | C17: 0.0259 | D17: 0.0167 | E17: 0.0104 | F17: 0.0104
A18: norg
B24: Sources | C24: Gachene et al. (2024)
C25: ISRIC
C27: Missing data

Sheet Soils_Vertis_p7
C1: Layer | N1: conversion factors
A2: Parameter | B2: unit | C2: 7 | D2: 7-20 | E2: 20-47 | F2: 47-65 | G2: 65-85 | H2: 85-110 | I2: 110-130 | J2: 130-150 | K2: 150-175 | N2: g cm^3 to kg/dm^3 | O2: 1
A3: depth, mm | C3: 180 | D3: =(41-18)*10 -> 230 | E3: =(74-14)*10 -> 600 | F3: =(150-74)*10 -> 760 | G3: =(85-65)*10 -> 200 | H3: =(110-85)*10 -> 250
A4: depth, cm | C4: =C3/10 -> 18 | D4: =D3/10 -> 23 | E4: =E3/10 -> 60 | F4: =F3/10 -> 76 | G4: =G3/10 -> 20 | H4: =H3/10 -> 25
A6: ph | B6: - | C6: 6.83 | D6: 6.02 | E6: 6.25 | F6: 6.22 | N6: second to minute | O6: 60
A7: bd | B7: kg/dm^3 | C7: 1.14 | D7: 1.14 | E7: 1.05 | F7: 1.13
A9: clay | B9: kg/kg | C9: 0.5357 | D9: 0.6357 | E9: 0.5947 | F9: 0.56
A10: sand | B10: kg/kg | C10: 0.2644 | D10: 0.2443 | E10: 0.2257 | F10: 0.364
A11: silt | B11: kg/kg | C11: 0.199 | D11: 0.12 | E11: 0.1796 | F11: 0.58
A13: ksat | B13: cm/min | C13: 0.25 | D13: 0.25 | E13: 0.41 | F13: 0.2
A14: wcmax | B14: dm^3/m^3 | C14: 439.2 | D14: 423 | E14: 440 | F14: 442.4 | G14: 41.73 | H14: 41.93
A15: wcmin | B15: dm^3/m^3 | C15: 363 | D15: 360 | E15: 390 | F15: 390.7 | G15: =35.77 -> 35.77 | H15: 38.77
A17: corg | B17: kg/kg | C17: 0.0259 | D17: 0.0167 | E17: 0.0104 | F17: 0.0104
A18: norg
B24: Sources | C24: Gachene et al. (2024)
C25: ISRIC
C27: Missing data

Sheet Soils_Vertis_p12
C1: Layer | N1: conversion factors
A2: Parameter | B2: unit | C2: 7 | D2: 7-20 | E2: 20-47 | F2: 47-65 | G2: 65-85 | H2: 85-110 | I2: 110-130 | J2: 130-150 | K2: 150-175 | N2: g cm^3 to kg/dm^3 | O2: 1
A3: depth, mm | C3: 180 | D3: =(41-18)*10 -> 230 | E3: =(74-14)*10 -> 600 | F3: =(150-74)*10 -> 760 | G3: =(85-65)*10 -> 200 | H3: =(110-85)*10 -> 250
A4: depth, cm | C4: =C3/10 -> 18 | D4: =D3/10 -> 23 | E4: =E3/10 -> 60 | F4: =F3/10 -> 76 | G4: =G3/10 -> 20 | H4: =H3/10 -> 25
A6: ph | B6: - | C6: 6.83 | D6: 6.02 | E6: 6.25 | F6: 6.22 | N6: second to minute | O6: 60
A7: bd | B7: kg/dm^3 | C7: 1.19 | D7: 1.1 | E7: 1.1 | F7: 1.1
A9: clay | B9: kg/kg | C9: 0.3551 | D9: 0.4342 | E9: 0.4545 | F9: 0.6
A10: sand | B10: kg/kg | C10: 0.5588 | D10: 0.4986 | E10: 0.4383 | F10: 0.3
A11: silt | B11: kg/kg | C11: 0.0871 | D11: 0.0672 | E11: 0.1072 | F11: 0.1
A13: ksat | B13: cm/min | C13: =Soils_Vertis_p7!C13 -> 0.25 | D13: =Soils_Vertis_p7!D13 -> 0.25 | E13: =Soils_Vertis_p7!E13 -> 0.41 | F13: =Soils_Vertis_p7!F13 -> 0.2
A14: wcmax | B14: dm^3/m^3 | C14: 420.6 | D14: 562.9 | E14: 416.7 | F14: 442.4 | G14: 41.73 | H14: 41.93
A15: wcmin | B15: dm^3/m^3 | C15: 359.5 | D15: 401.4 | E15: 300.6 | F15: 390.7 | G15: =35.77 -> 35.77 | H15: 38.77
A17: corg | B17: kg/kg | C17: 0.0259 | D17: 0.0167 | E17: 0.0104 | F17: 0.0104
A18: norg
B24: Sources | C24: Gachene et al. (2024)
C25: ISRIC
C27: Missing data

Sheet Soils_wgt_avg
C1: Layer | N1: conversion factors
A2: Parameter | B2: unit | C2: 7 | D2: 7-20 | E2: 20-47 | F2: 47-65 | G2: 65-85 | H2: 85-110 | I2: 110-130 | J2: 130-150 | K2: 150-175 | N2: g cm^3 to kg/dm^3 | O2: 1
A3: depth, mm | C3: 180 | D3: =(41-18)*10 -> 230 | E3: =(74-14)*10 -> 600 | F3: =(150-74)*10 -> 760 | G3: =(85-65)*10 -> 200 | H3: =(110-85)*10 -> 250
A4: depth, cm | C4: =C3/10 -> 18 | D4: =D3/10 -> 23 | E4: =E3/10 -> 60 | F4: =F3/10 -> 76 | G4: =G3/10 -> 20 | H4: =H3/10 -> 25
A6: ph | B6: - | C6: =SUM(Soils_Vertis_p7!C6*$D$31,Soils_Vertis_p4!C6*$D$30,Soils_Vertis_p12!C6*$D$32,Soil_parameters_Ferral_P8!C6*Soils_wgt_avg!$D$33) -> 6.83 | D6: =SUM(Soils_Vertis_p7!D6*$D$31,Soils_Vertis_p4!D6*$D$30,Soils_Vertis_p12!D6*$D$32,Soil_parameters_Ferral_P8!D6*Soils_wgt_avg!$D$33) -> 6.02 | E6: =SUM(Soils_Vertis_p7!E6*$D$31,Soils_Vertis_p4!E6*$D$30,Soils_Vertis_p12!E6*$D$32,Soil_parameters_Ferral_P8!E6*Soils_wgt_avg!$D$33) -> 6.25 | F6: =SUM(Soils_Vertis_p7!F6*$D$31,Soils_Vertis_p4!F6*$D$30,Soils_Vertis_p12!F6*$D$32,Soil_parameters_Ferral_P8!F6*Soils_wgt_avg!$D$33) -> 6.22 | G6: =SUM(Soils_Vertis_p7!G6*$D$31,Soils_Vertis_p4!G6*$D$30,Soils_Vertis_p12!G6*$D$32,Soil_parameters_Ferral_P8!G6*Soils_wgt_avg!$D$33) -> 0 | H6: =SUM(Soils_Vertis_p7!H6*$D$31,Soils_Vertis_p4!H6*$D$30,Soils_Vertis_p12!H6*$D$32,Soil_parameters_Ferral_P8!H6*Soils_wgt_avg!$D$33) -> 0 | N6: second to minute | O6: 60
A7: bd | B7: kg/dm^3 | C7: =SUM(Soils_Vertis_p7!C7*$D$31,Soils_Vertis_p4!C7*$D$30,Soils_Vertis_p12!C7*$D$32,Soil_parameters_Ferral_P8!C7*Soils_wgt_avg!$D$33) -> 1.17 | D7: =SUM(Soils_Vertis_p7!D7*$D$31,Soils_Vertis_p4!D7*$D$30,Soils_Vertis_p12!D7*$D$32,Soil_parameters_Ferral_P8!D7*Soils_wgt_avg!$D$33) -> 1.244 | E7: =SUM(Soils_Vertis_p7!E7*$D$31,Soils_Vertis_p4!E7*$D$30,Soils_Vertis_p12!E7*$D$32,Soil_parameters_Ferral_P8!E7*Soils_wgt_avg!$D$33) -> 1.288 | F7: =SUM(Soils_Vertis_p7!F7*$D$31,Soils_Vertis_p4!F7*$D$30,Soils_Vertis_p12!F7*$D$32,Soil_parameters_Ferral_P8!F7*Soils_wgt_avg!$D$33) -> 1.268 | G7: =SUM(Soils_Vertis_p7!G7*$D$31,Soils_Vertis_p4!G7*$D$30,Soils_Vertis_p12!G7*$D$32,Soil_parameters_Ferral_P8!G7*Soils_wgt_avg!$D$33) -> 0 | H7: =SUM(Soils_Vertis_p7!H7*$D$31,Soils_Vertis_p4!H7*$D$30,Soils_Vertis_p12!H7*$D$32,Soil_parameters_Ferral_P8!H7*Soils_wgt_avg!$D$33) -> 0
C8: =SUM(Soils_Vertis_p7!C8*$D$31,Soils_Vertis_p4!C8*$D$30,Soils_Vertis_p12!C8*$D$32,Soil_parameters_Ferral_P8!C8*Soils_wgt_avg!$D$33) -> 0 | D8: =SUM(Soils_Vertis_p7!D8*$D$31,Soils_Vertis_p4!D8*$D$30,Soils_Vertis_p12!D8*$D$32,Soil_parameters_Ferral_P8!D8*Soils_wgt_avg!$D$33) -> 0 | E8: =SUM(Soils_Vertis_p7!E8*$D$31,Soils_Vertis_p4!E8*$D$30,Soils_Vertis_p12!E8*$D$32,Soil_parameters_Ferral_P8!E8*Soils_wgt_avg!$D$33) -> 0 | F8: =SUM(Soils_Vertis_p7!F8*$D$31,Soils_Vertis_p4!F8*$D$30,Soils_Vertis_p12!F8*$D$32,Soil_parameters_Ferral_P8!F8*Soils_wgt_avg!$D$33) -> 0 | G8: =SUM(Soils_Vertis_p7!G8*$D$31,Soils_Vertis_p4!G8*$D$30,Soils_Vertis_p12!G8*$D$32,Soil_parameters_Ferral_P8!G8*Soils_wgt_avg!$D$33) -> 0 | H8: =SUM(Soils_Vertis_p7!H8*$D$31,Soils_Vertis_p4!H8*$D$30,Soils_Vertis_p12!H8*$D$32,Soil_parameters_Ferral_P8!H8*Soils_wgt_avg!$D$33) -> 0
A9: clay | B9: kg/kg | C9: =SUM(Soils_Vertis_p7!C9*$D$31,Soils_Vertis_p4!C9*$D$30,Soils_Vertis_p12!C9*$D$32,Soil_parameters_Ferral_P8!C9*Soils_wgt_avg!$D$33) -> 0.25142 | D9: =SUM(Soils_Vertis_p7!D9*$D$31,Soils_Vertis_p4!D9*$D$30,Soils_Vertis_p12!D9*$D$32,Soil_parameters_Ferral_P8!D9*Soils_wgt_avg!$D$33) -> 0.29872 | E9: =SUM(Soils_Vertis_p7!E9*$D$31,Soils_Vertis_p4!E9*$D$30,Soils_Vertis_p12!E9*$D$32,Soil_parameters_Ferral_P8!E9*Soils_wgt_avg!$D$33) -> 0.3111 | F9: =SUM(Soils_Vertis_p7!F9*$D$31,Soils_Vertis_p4!F9*$D$30,Soils_Vertis_p12!F9*$D$32,Soil_parameters_Ferral_P8!F9*Soils_wgt_avg!$D$33) -> 0.4064 | G9: =SUM(Soils_Vertis_p7!G9*$D$31,Soils_Vertis_p4!G9*$D$30,Soils_Vertis_p12!G9*$D$32,Soil_parameters_Ferral_P8!G9*Soils_wgt_avg!$D$33) -> 0 | H9: =SUM(Soils_Vertis_p7!H9*$D$31,Soils_Vertis_p4!H9*$D$30,Soils_Vertis_p12!H9*$D$32,Soil_parameters_Ferral_P8!H9*Soils_wgt_avg!$D$33) -> 0
A10: sand | B10: kg/kg | C10: =SUM(Soils_Vertis_p7!C10*$D$31,Soils_Vertis_p4!C10*$D$30,Soils_Vertis_p12!C10*$D$32,Soil_parameters_Ferral_P8!C10*Soils_wgt_avg!$D$33) -> 0.68092 | D10: =SUM(Soils_Vertis_p7!D10*$D$31,Soils_Vertis_p4!D10*$D$30,Soils_Vertis_p12!D10*$D$32,Soil_parameters_Ferral_P8!D10*Soils_wgt_avg!$D$33) -> 0.63916 | E10: =SUM(Soils_Vertis_p7!E10*$D$31,Soils_Vertis_p4!E10*$D$30,Soils_Vertis_p12!E10*$D$32,Soil_parameters_Ferral_P8!E10*Soils_wgt_avg!$D$33) -> 0.60698 | F10: =SUM(Soils_Vertis_p7!F10*$D$31,Soils_Vertis_p4!F10*$D$30,Soils_Vertis_p12!F10*$D$32,Soil_parameters_Ferral_P8!F10*Soils_wgt_avg!$D$33) -> 0.508 | G10: =SUM(Soils_Vertis_p7!G10*$D$31,Soils_Vertis_p4!G10*$D$30,Soils_Vertis_p12!G10*$D$32,Soil_parameters_Ferral_P8!G10*Soils_wgt_avg!$D$33) -> 0 | H10: =SUM(Soils_Vertis_p7!H10*$D$31,Soils_Vertis_p4!H10*$D$30,Soils_Vertis_p12!H10*$D$32,Soil_parameters_Ferral_P8!H10*Soils_wgt_avg!$D$33) -> 0
A11: silt | B11: kg/kg | C11: =SUM(Soils_Vertis_p7!C11*$D$31,Soils_Vertis_p4!C11*$D$30,Soils_Vertis_p12!C11*$D$32,Soil_parameters_Ferral_P8!C11*Soils_wgt_avg!$D$33) -> 0.06826 | D11: =SUM(Soils_Vertis_p7!D11*$D$31,Soils_Vertis_p4!D11*$D$30,Soils_Vertis_p12!D11*$D$32,Soil_parameters_Ferral_P8!D11*Soils_wgt_avg!$D$33) -> 0.06432 | E11: =SUM(Soils_Vertis_p7!E11*$D$31,Soils_Vertis_p4!E11*$D$30,Soils_Vertis_p12!E11*$D$32,Soil_parameters_Ferral_P8!E11*Soils_wgt_avg!$D$33) -> 0.08032 | F11: =SUM(Soils_Vertis_p7!F11*$D$31,Soils_Vertis_p4!F11*$D$30,Soils_Vertis_p12!F11*$D$32,Soil_parameters_Ferral_P8!F11*Soils_wgt_avg!$D$33) -> 0.076 | G11: =SUM(Soils_Vertis_p7!G11*$D$31,Soils_Vertis_p4!G11*$D$30,Soils_Vertis_p12!G11*$D$32,Soil_parameters_Ferral_P8!G11*Soils_wgt_avg!$D$33) -> 0 | H11: =SUM(Soils_Vertis_p7!H11*$D$31,Soils_Vertis_p4!H11*$D$30,Soils_Vertis_p12!H11*$D$32,Soil_parameters_Ferral_P8!H11*Soils_wgt_avg!$D$33) -> 0
A13: ksat | B13: cm/min | C13: =SUM(Soils_Vertis_p7!C13*$D$31,Soils_Vertis_p4!C13*$D$30,Soils_Vertis_p12!C13*$D$32,Soil_parameters_Ferral_P8!C13*Soils_wgt_avg!$D$33) -> 0.29 | D13: =SUM(Soils_Vertis_p7!D13*$D$31,Soils_Vertis_p4!D13*$D$30,Soils_Vertis_p12!D13*$D$32,Soil_parameters_Ferral_P8!D13*Soils_wgt_avg!$D$33) -> 0.1906 | E13: =SUM(Soils_Vertis_p7!E13*$D$31,Soils_Vertis_p4!E13*$D$30,Soils_Vertis_p12!E13*$D$32,Soil_parameters_Ferral_P8!E13*Soils_wgt_avg!$D$33) -> 0.27268 | F13: =SUM(Soils_Vertis_p7!F13*$D$31,Soils_Vertis_p4!F13*$D$30,Soils_Vertis_p12!F13*$D$32,Soil_parameters_Ferral_P8!F13*Soils_wgt_avg!$D$33) -> 0.1592 | G13: =SUM(Soils_Vertis_p7!G13*$D$31,Soils_Vertis_p4!G13*$D$30,Soils_Vertis_p12!G13*$D$32,Soil_parameters_Ferral_P8!G13*Soils_wgt_avg!$D$33) -> 0 | H13: =SUM(Soils_Vertis_p7!H13*$D$31,Soils_Vertis_p4!H13*$D$30,Soils_Vertis_p12!H13*$D$32,Soil_parameters_Ferral_P8!H13*Soils_wgt_avg!$D$33) -> 0
A14: wcmax | B14: dm^3/m^3 | C14: =SUM(Soils_Vertis_p7!C14*$D$31,Soils_Vertis_p4!C14*$D$30,Soils_Vertis_p12!C14*$D$32,Soil_parameters_Ferral_P8!C14*Soils_wgt_avg!$D$33) -> 342.6 | D14: =SUM(Soils_Vertis_p7!D14*$D$31,Soils_Vertis_p4!D14*$D$30,Soils_Vertis_p12!D14*$D$32,Soil_parameters_Ferral_P8!D14*Soils_wgt_avg!$D$33) -> 456.74 | E14: =SUM(Soils_Vertis_p7!E14*$D$31,Soils_Vertis_p4!E14*$D$30,Soils_Vertis_p12!E14*$D$32,Soil_parameters_Ferral_P8!E14*Soils_wgt_avg!$D$33) -> 389.46 | F14: =SUM(Soils_Vertis_p7!F14*$D$31,Soils_Vertis_p4!F14*$D$30,Soils_Vertis_p12!F14*$D$32,Soil_parameters_Ferral_P8!F14*Soils_wgt_avg!$D$33) -> 439.24 | G14: =SUM(Soils_Vertis_p7!G14*$D$31,Soils_Vertis_p4!G14*$D$30,Soils_Vertis_p12!G14*$D$32,Soil_parameters_Ferral_P8!G14*Soils_wgt_avg!$D$33) -> 41.73 | H14: =SUM(Soils_Vertis_p7!H14*$D$31,Soils_Vertis_p4!H14*$D$30,Soils_Vertis_p12!H14*$D$32,Soil_parameters_Ferral_P8!H14*Soils_wgt_avg!$D$33) -> 41.93
A15: wcmin | B15: dm^3/m^3 | C15: =SUM(Soils_Vertis_p7!C15*$D$31,Soils_Vertis_p4!C15*$D$30,Soils_Vertis_p12!C15*$D$32,Soil_parameters_Ferral_P8!C15*Soils_wgt_avg!$D$33) -> 231.46 | D15: =SUM(Soils_Vertis_p7!D15*$D$31,Soils_Vertis_p4!D15*$D$30,Soils_Vertis_p12!D15*$D$32,Soil_parameters_Ferral_P8!D15*Soils_wgt_avg!$D$33) -> 283.16 | E15: =SUM(Soils_Vertis_p7!E15*$D$31,Soils_Vertis_p4!E15*$D$30,Soils_Vertis_p12!E15*$D$32,Soil_parameters_Ferral_P8!E15*Soils_wgt_avg!$D$33) -> 219.92 | F15: =SUM(Soils_Vertis_p7!F15*$D$31,Soils_Vertis_p4!F15*$D$30,Soils_Vertis_p12!F15*$D$32,Soil_parameters_Ferral_P8!F15*Soils_wgt_avg!$D$33) -> 297.82 | G15: =SUM(Soils_Vertis_p7!G15*$D$31,Soils_Vertis_p4!G15*$D$30,Soils_Vertis_p12!G15*$D$32,Soil_parameters_Ferral_P8!G15*Soils_wgt_avg!$D$33) -> 35.77 | H15: =SUM(Soils_Vertis_p7!H15*$D$31,Soils_Vertis_p4!H15*$D$30,Soils_Vertis_p12!H15*$D$32,Soil_parameters_Ferral_P8!H15*Soils_wgt_avg!$D$33) -> 38.77
A17: corg | B17: kg/kg | C17: 0.0259 | D17: 0.0167 | E17: 0.0104 | F17: 0.0104
A18: norg
B24: Sources | C24: Gachene et al. (2024)
C25: ISRIC
C27: Missing data
B30: Weights | C30: Vertis p4 | D30: 0
C31: Vertis p7 | D31: 0
C32: Vertis p12 | D32: 0.6
C33: Ferral p8 | D33: 0.4
C34: Planos p13 | D34: 0

Sheet Soil_Ferral_ISRIC_KE007 (2)
C1: Layer | N1: conversion factors
A2: Parameter | B2: unit | C2: 1 | D2: 2 | E2: 3 | F2: 4 | G2: 5 | H2: 6 | I2: 7 | J2: 8 | K2: 9 | N2: g cm^3 to kg/dm^3 | O2: 1
A3: depth, mm | C3: 190 | D3: =(31-19)*10 -> 120 | E3: =(50-30)*10 -> 200 | F3: =(80-50)*10 -> 300 | G3: =(85-65)*10 -> 200 | H3: =(110-85)*10 -> 250
A4: depth, cm | C4: =C3/10 -> 19 | D4: =D3/10 -> 12 | E4: =E3/10 -> 20 | F4: =F3/10 -> 30 | G4: =G3/10 -> 20 | H4: =H3/10 -> 25
A6: ph | B6: - | C6: 6.83 | D6: 6.02 | E6: 6.25 | F6: 6.22 | N6: second to minute | O6: 60
A7: bd | B7: kg/dm^3 | C7: 1.19 | D7: 1.19 | E7: 1.22
A9: clay | B9: kg/kg | C9: 0.716 | D9: 0.859 | E9: 0.839 | F9: 0.838
A10: sand | B10: kg/kg | C10: 0.106 | D10: 0.09 | E10: 0.081 | F10: 0.007
A11: silt | B11: kg/kg | C11: =1-C9-C10 -> 0.178 | D11: =1-D9-D10 -> 0.051 | E11: =1-E9-E10 -> 0.08 | F11: =1-F9-F10 -> 0.155
A13: ksat | B13: cm/min | C13: 0.35 | D13: 0.1015 | E13: 0.0667 | F13: 0.098
A14: wcmax | B14: dm^3/m^3 | C14: =225.6 -> 225.6 | D14: =297.5 -> 297.5 | E14: =348.6 -> 348.6 | F14: =434.5 -> 434.5 | G14: 41.73 | H14: 41.93
A15: wcmin | B15: dm^3/m^3 | C15: =39.4 -> 39.4 | D15: =105.8 -> 105.8 | E15: =98.9 -> 98.9 | F15: =158.5 -> 158.5 | G15: =35.77 -> 35.77 | H15: 38.77
A17: corg | B17: kg/kg | C17: 0.0259 | D17: 0.0167 | E17: 0.0104 | F17: 0.0104
A18: norg
B24: Sources | C24: Gachene et al. (2024)
C25: ISRIC
C27: Missing data

Sheet ISRIC Reference soils
A2: Ferralsols | B2: 6 | C2: Mollic- Ferralsol (Humic Eutric Clayic) | F2: https://museum.isric.org/monoliths/reference-soil-kenya-06
B3: 7 | C3: Haplic- Ferralsol (Humic Dystric Clayic) | F3: https://museum.isric.org/monoliths/reference-soil-kenya-07
B4: 9 | C4: Eutri-Rhodic Ferralsol | F4: https://museum.isric.org/monoliths/reference-soil-kenya-09
B5: 11 | C5: Lixic-Vetic- Ferralsol (Eutric Rhodic) | F5: https://museum.isric.org/monoliths/reference-soil-kenya-11
B6: 29 | C6: Acric- Ferralsol (Dystric Rhodic | F6: https://museum.isric.org/monoliths/reference-soil-kenya-29
B7: 40 | C7: Umbric- Ferralsol (Humic Alumic Clayic) | F7: https://museum.isric.org/monoliths/reference-soil-kenya-40
B8: 48 | C8: Haplic- Ferralsol (Humic Dystric Clayic) | F8: https://museum.isric.org/monoliths/reference-soil-kenya-48
A11: Vertisols

Sheet Soil_Ferral_ISRIC_KE007
C1: Layer | N1: conversion factors
A2: Parameter | B2: unit | C2: 1 | D2: 2 | E2: 3 | F2: 4 | G2: 5 | H2: 6 | I2: 7 | J2: 8 | K2: 9 | N2: g cm^3 to kg/dm^3 | O2: 1
A3: depth, mm | C3: 190 | D3: =(31-19)*10 -> 120 | E3: =(50-30)*10 -> 200 | F3: =(80-50)*10 -> 300 | G3: =(85-65)*10 -> 200 | H3: =(110-85)*10 -> 250
A4: depth, cm | C4: =C3/10 -> 19 | D4: =D3/10 -> 12 | E4: =E3/10 -> 20 | F4: =F3/10 -> 30 | G4: =G3/10 -> 20 | H4: =H3/10 -> 25
A6: ph | B6: - | C6: 6.83 | D6: 6.02 | E6: 6.25 | F6: 6.22 | N6: second to minute | O6: 60
A7: bd | B7: kg/dm^3 | C7: 1.19 | D7: 1.19 | E7: 1.22
A9: clay | B9: kg/kg | C9: 0.716 | D9: 0.859 | E9: 0.839 | F9: 0.838
A10: sand | B10: kg/kg | C10: 0.106 | D10: 0.09 | E10: 0.081 | F10: 0.007
A11: silt | B11: kg/kg | C11: =1-C9-C10 -> 0.178 | D11: =1-D9-D10 -> 0.051 | E11: =1-E9-E10 -> 0.08 | F11: =1-F9-F10 -> 0.155
A13: ksat | B13: cm/min | C13: 0.35 | D13: 0.1015 | E13: 0.0667 | F13: 0.098
A14: wcmax | B14: dm^3/m^3 | C14: =225.6 -> 225.6 | D14: =297.5 -> 297.5 | E14: =348.6 -> 348.6 | F14: =434.5 -> 434.5 | G14: 41.73 | H14: 41.93
A15: wcmin | B15: dm^3/m^3 | C15: =39.4 -> 39.4 | D15: =105.8 -> 105.8 | E15: =98.9 -> 98.9 | F15: =158.5 -> 158.5 | G15: =35.77 -> 35.77 | H15: 38.77
A17: corg | B17: kg/kg | C17: 0.0259 | D17: 0.0167 | E17: 0.0104 | F17: 0.0104
A18: norg
B24: Sources | C24: Gachene et al. (2024)
C25: ISRIC
C27: Missing data

Sheet Soil_parameters_Ferral_ISRIC
C1: Layer | N1: conversion factors
A2: Parameter | B2: unit | C2: 31 | D2: 31-65 | E2: 65-85 | F2: 85-125 | G2: 65-85 | H2: 85-110 | I2: 110-130 | J2: 130-150 | K2: 150-175 | N2: g cm^3 to kg/dm^3 | O2: 1
A3: depth, mm | C3: 31 | D3: =(20-7)*10 -> 130 | E3: =(47-20)*10 -> 270 | F3: =(65-47)*10 -> 180 | G3: =(85-65)*10 -> 200 | H3: =(110-85)*10 -> 250
A4: depth, cm | C4: =C3/10 -> 3.1 | D4: =D3/10 -> 13 | E4: =E3/10 -> 27 | F4: =F3/10 -> 18 | G4: =G3/10 -> 20 | H4: =H3/10 -> 25
A6: ph | B6: - | N6: second to minute | O6: 60
A7: bd | B7: kg/dm^3
A9: clay | B9: kg/kg
A10: sand | B10: kg/kg
A11: silt | B11: kg/kg
A13: ksat | B13: cm/min
A14: wcmax | B14: dm^3/m^3 | C14: =440.4 -> 440.4 | D14: =297.8 -> 297.8 | E14: =372 -> 372 | F14: =423.4 -> 423.4 | G14: 41.73 | H14: 41.93
A15: wcmin | B15: dm^3/m^3 | C15: =353.1 -> 353.1 | D15: =200.9 -> 200.9 | E15: =252.2 -> 252.2 | F15: =267 -> 267 | G15: =35.77 -> 35.77 | H15: 38.77
A17: corg
A18: norg
B24: Sources | C24: Gachene et al. (2024)
C25: ISRIC
C27: Missing data

Sheet Soil_parameters_Ferral_Mean
C1: Layer | N1: conversion factors
A2: Parameter | B2: unit | C2: 7 | D2: 7-20 | E2: 20-47 | F2: 47-65 | G2: 65-85 | H2: 85-110 | I2: 110-130 | J2: 130-150 | K2: 150-175 | N2: g cm^3 to kg/dm^3 | O2: 1
A3: depth, mm | C3: 70 | D3: =(20-7)*10 -> 130 | E3: =(47-20)*10 -> 270 | F3: =(65-47)*10 -> 180 | G3: =(85-65)*10 -> 200 | H3: =(110-85)*10 -> 250
A4: depth, cm | C4: =C3/10 -> 7 | D4: =D3/10 -> 13 | E4: =E3/10 -> 27 | F4: =F3/10 -> 18 | G4: =G3/10 -> 20 | H4: =H3/10 -> 25
A6: ph | B6: - | N6: second to minute | O6: 60
A7: bd | B7: kg/dm^3
A9: clay | B9: kg/kg
A10: sand | B10: kg/kg
A11: silt | B11: kg/kg
A13: ksat | B13: cm/min
A14: wcmax | B14: dm^3/m^3 | C14: =AVERAGE(Soil_parameters_Ferral_P8!C14,Soil_parameters_Ferral_P14!C14) -> 333 | D14: =AVERAGE(Soil_parameters_Ferral_P8!D14,Soil_parameters_Ferral_P14!D14) -> 297.65 | E14: =AVERAGE(Soil_parameters_Ferral_P8!E14,Soil_parameters_Ferral_P14!E14) -> 360.3 | F14: =AVERAGE(Soil_parameters_Ferral_P8!F14,Soil_parameters_Ferral_P14!F14) -> 428.95 | G14: 41.73 | H14: 41.93
A15: wcmin | B15: dm^3/m^3 | C15: =AVERAGE(Soil_parameters_Ferral_P8!C15,Soil_parameters_Ferral_P14!C15) -> 196.25 | D15: =AVERAGE(Soil_parameters_Ferral_P8!D15,Soil_parameters_Ferral_P14!D15) -> 153.35 | E15: =AVERAGE(Soil_parameters_Ferral_P8!E15,Soil_parameters_Ferral_P14!E15) -> 175.55 | F15: =AVERAGE(Soil_parameters_Ferral_P8!F15,Soil_parameters_Ferral_P14!F15) -> 212.75 | G15: =35.77 -> 35.77 | H15: 38.77
A17: corg
A18: norg
B24: Sources | C24: Gachene et al. (2024)
C25: ISRIC
C27: Missing data

Sheet Soil_Ferral_ISRIC_KE009
C1: Layer | N1: conversion factors
A2: Parameter | B2: unit | C2: 1 | D2: 2 | E2: 3 | F2: 4 | G2: 5 | H2: 6 | I2: 7 | J2: 8 | K2: 9 | N2: g cm^3 to kg/dm^3 | O2: 1
A3: depth, mm | C3: 190 | D3: =(31-19)*10 -> 120 | E3: =(50-30)*10 -> 200 | F3: =(80-50)*10 -> 300 | G3: =(85-65)*10 -> 200 | H3: =(110-85)*10 -> 250
A4: depth, cm | C4: =C3/10 -> 19 | D4: =D3/10 -> 12 | E4: =E3/10 -> 20 | F4: =F3/10 -> 30 | G4: =G3/10 -> 20 | H4: =H3/10 -> 25
A6: ph | B6: - | C6: 6.83 | D6: 6.02 | E6: 6.25 | F6: 6.22 | N6: second to minute | O6: 60
A7: bd | B7: kg/dm^3 | C7: 1.19 | D7: 1.19 | E7: 1.22
A9: clay | B9: kg/kg | C9: 0.546 | D9: 0.64 | E9: 0.647 | F9: 0.659
A10: sand | B10: kg/kg | C10: 0.311 | D10: 0.278 | E10: 0.286 | F10: 0.277
A11: silt | B11: kg/kg | C11: =1-C9-C10 -> 0.143 | D11: =1-D9-D10 -> 0.082 | E11: =1-E9-E10 -> 0.067 | F11: =1-F9-F10 -> 0.064
A13: ksat | B13: cm/min | C13: 0.35 | D13: 0.1015 | E13: 0.0667 | F13: 0.098
A14: wcmax | B14: dm^3/m^3 | C14: =225.6 -> 225.6 | D14: =297.5 -> 297.5 | E14: =348.6 -> 348.6 | F14: =434.5 -> 434.5 | G14: 41.73 | H14: 41.93
A15: wcmin | B15: dm^3/m^3 | C15: =39.4 -> 39.4 | D15: =105.8 -> 105.8 | E15: =98.9 -> 98.9 | F15: =158.5 -> 158.5 | G15: =35.77 -> 35.77 | H15: 38.77
A17: corg | B17: kg/kg | C17: 0.0259 | D17: 0.0167 | E17: 0.0104 | F17: 0.0104
A18: norg
B24: Sources | C24: Gachene et al. (2024)
C25: ISRIC
C27: Missing data

Sheet Soil_parameters_Ferral_P14
C1: Layer | N1: conversion factors
A2: Parameter | B2: unit | C2: 31 | D2: 31-65 | E2: 65-85 | F2: 85-125 | G2: 65-85 | H2: 85-110 | I2: 110-130 | J2: 130-150 | K2: 150-175 | N2: g cm^3 to kg/dm^3 | O2: 1
A3: depth, mm | C3: 31 | D3: =(20-7)*10 -> 130 | E3: =(47-20)*10 -> 270 | F3: =(65-47)*10 -> 180 | G3: =(85-65)*10 -> 200 | H3: =(110-85)*10 -> 250
A4: depth, cm | C4: =C3/10 -> 3.1 | D4: =D3/10 -> 13 | E4: =E3/10 -> 27 | F4: =F3/10 -> 18 | G4: =G3/10 -> 20 | H4: =H3/10 -> 25
A6: ph | B6: - | N6: second to minute | O6: 60
A7: bd | B7: kg/dm^3
A9: clay | B9: kg/kg
A10: sand | B10: kg/kg
A11: silt | B11: kg/kg
A13: ksat | B13: cm/min
A14: wcmax | B14: dm^3/m^3 | C14: =440.4 -> 440.4 | D14: =297.8 -> 297.8 | E14: =372 -> 372 | F14: =423.4 -> 423.4 | G14: 41.73 | H14: 41.93
A15: wcmin | B15: dm^3/m^3 | C15: =353.1 -> 353.1 | D15: =200.9 -> 200.9 | E15: =252.2 -> 252.2 | F15: =267 -> 267 | G15: =35.77 -> 35.77 | H15: 38.77
A17: corg
A18: norg
B24: Sources | C24: Gachene et al. (2024)
C25: ISRIC
C27: Missing data

Sheet Soil_parameters (2)
C1: Layer | N1: conversion factors
A2: Parameter | B2: unit | C2: 7 | D2: 7-20 | E2: 20-47 | F2: 47-65 | G2: 65-85 | H2: 85-110 | I2: 110-130 | J2: 130-150 | K2: 150-175 | N2: g cm^3 to kg/dm^3 | O2: 1
A3: depth, mm | C3: 70 | D3: =(20-7)*10 -> 130 | E3: =(47-20)*10 -> 270 | F3: =(65-47)*10 -> 180 | G3: =(85-65)*10 -> 200 | H3: =(110-85)*10 -> 250
A4: depth, cm | C4: =C3/10 -> 7 | D4: =D3/10 -> 13 | E4: =E3/10 -> 27 | F4: =F3/10 -> 18 | G4: =G3/10 -> 20 | H4: =H3/10 -> 25
A6: ph | B6: - | C6: 5.4 | D6: 5.4 | E6: 5.5 | F6: 5.5 | G6: 5.4 | H6: 5.4 | N6: second to minute | O6: 60
A7: bd | B7: kg/dm^3 | C7: 1.14 | D7: 1.14 | E7: 1.14 | F7: 1.05 | G7: 1.05 | H7: 1.13
A9: clay | B9: kg/kg | C9: 0.603 | D9: 0.63 | E9: 0.543 | F9: 0.555 | G9: 0.537 | H9: 0.533
A10: sand | B10: kg/kg | C10: 0.061 | D10: 0.057 | E10: 0.08 | F10: 0.073 | G10: 0.089 | H10: 0.096
A11: silt | B11: kg/kg | C11: 0.337 | D11: 0.313 | E11: 0.378 | F11: 0.371 | G11: 0.375 | H11: 0.373
A13: ksat | B13: cm/min | C13: =0.25 -> 0.25 | D13: =0.25 -> 0.25 | E13: =0.25 -> 0.25 | F13: 0.41 | G13: 0.41 | H13: 0.2
A14: wcmax | B14: dm^3/m^3 | C14: =43.92 -> 43.92 | D14: =43.92 -> 43.92 | E14: =43.92 -> 43.92 | F14: 41.73 | G14: 41.73 | H14: 41.93
A15: wcmin | B15: dm^3/m^3 | C15: =36.33 -> 36.33 | D15: =36.33 -> 36.33 | E15: =36.33 -> 36.33 | F15: =35.77 -> 35.77 | G15: =35.77 -> 35.77 | H15: 38.77
A17: corg | C17: 0.0194 | D17: 0.012 | E17: 0.002 | F17: 0.0019 | G17: 0.0019 | H17: 0.0011
A18: norg | C18: 0.0021 | D18: 0.0016 | E18: 0.0007 | F18: 0.0007
B24: Sources | C24: Gachene et al. (2024)
C25: ISRIC
C27: Missing data

Sheet Cattle density
B1: all
A2: population | B2: 1500
A3: area | B3: 13000
A4: density (head/ha) | B4: =B2/B3 -> 0.11538462
A7: grazing periodicity parameter
B8: 10
A10: months per year | B10: =12/B8 -> 1.2
A11: hours per day | B11: 6
A13: density during grazing | B13: =B4*B8*10/B11 -> 1.9230769
B15: =(B8*B4)*10/B11 -> 1.9230769
A18: reverse calculation | B18: =B13*(6/10)*(1/12) -> 0.096153846

Sheet Tree density
A2: mean crown area Acacia | B2: 10
A3: mean crown area Burkea | B3: 18
A5: mean crown area | B5: =B2*0.7+0.3*B3 -> 12.4
A6: canopy cover | B6: 0.04
A9: tree density | B9: =10000*(-1)*LOG(1-B6,2.7814)/B5 -> 32.182239

Sheet Soil_references
A2: Ferralsol 48 | B2: https://museum.isric.org/monoliths/reference-soil-kenya-48
A3: Ferralsol 11 - sandy ferralsol | C3: https://museum.isric.org/monoliths/reference-soil-kenya-11
A4: sandy ferralso | C4: https://museum.isric.org/monoliths/reference-soil-kenya-29
A5: very clayey Ferralsol | C5: https://museum.isric.org/monoliths/reference-soil-kenya-07 | I5: lists BD
A6: clayey Ferralsol | C6: https://museum.isric.org/monoliths/reference-soil-kenya-09
A7: moderately clayey Ferralsol | C7: https://museum.isric.org/monoliths/reference-soil-kenya-06 | I7: lists BD
A8: extremely clayey ferralsol | C8: https://museum.isric.org/monoliths/reference-soil-kenya-40

Sheet Wild_herbivores
A1: Species | B1: Type | C1: TLU Equivalent | D1: 44835 | E1: 45078 | F1: 45200 | G1: 45323 | H1: 45474 | I1: 45566 | O1: 44835 | P1: 45078 | Q1: 45200 | R1: 45323 | S1: 45474 | T1: 45566
A2: Buffalo | B2: Herbivore | C2: 1.8 | N2: Total number | O2: 2584 | P2: 752 | Q2: 778 | R2: 890 | S2: 429 | T2: =I18 -> 475
A3: Bush Duiker | B3: Herbivore | C3: 0.06 | F3: 1 | G3: 2 | N3: No species counted | O3: 14 | P3: 13 | Q3: 14 | R3: 14 | S3: 8 | T3: =I20 -> 7
A4: Bushbuck | B4: Herbivore | C4: 0.18 | D4: 1 | E4: 2
A5: Coke's Hartebeest | B5: Herbivore | C5: 0.5 | D5: 215
A6: Dik-Dik | B6: Herbivore | C6: 0.02 | D6: 3 | E6: 3 | F6: 4 | G6: 3
A7: Eland | B7: Herbivore | C7: 1.36 | D7: 35 | E7: 78 | F7: 36 | G7: 84 | H7: 62 | I7: 70
A8: Gerenuk | B8: Herbivore | C8: 0.16 | D8: 7 | E8: 5 | F8: 9 | G8: 1
A9: Grant's Gazelle | B9: Herbivore | C9: 0.16 | D9: 19 | E9: 39 | F9: 119 | G9: 33 | H9: 68 | I9: 43
A10: Impala | B10: Herbivore | C10: 0.172 | D10: 79 | E10: 91 | F10: 106 | G10: 107 | H10: 26 | I10: 109
A11: Lesser Kudu | B11: Herbivore | C11: 0.28 | D11: 9 | E11: 3 | F11: 16 | G11: 2 | H11: 1 | I11: 1
A12: Masai Giraffe | B12: Herbivore | C12: 3 | D12: 66 | E12: 60 | F12: 41 | G12: 122 | H12: 81 | I12: 45
A13: Reedbuck | B13: Herbivore | C13: 0.18 | G13: 1
A14: Steinbok | B14: Herbivore | C14: 0.044
A15: Thomson's Gazelle | B15: Herbivore | C15: 0.072 | D15: 176 | E15: 185 | F15: 174 | G15: 189 | H15: 73 | I15: 87
A16: Wildebeest | B16: Herbivore | C16: 0.56 | D16: 1273
A17: Zebra | B17: Herbivore | C17: 0.8 | D17: 657 | E17: 250 | F17: 217 | G17: 308 | H17: 95 | I17: 120
A18: TOTAL | D18: =SUM(D2:D9,D10:D13,D14:D15,D16:D17) -> 2540 | E18: =SUM(E2:E17) -> 716 | F18: =SUM(F2:F17) -> 723 | G18: =SUM(G2:G17) -> 852 | H18: =SUM(H2:H17) -> 406 | I18: =SUM(I2:I17) -> 475
A19: Total.TLU | D19: =SUMPRODUCT(D2:D17,$C$2:$C$17) -> 1624.76 | E19: =SUMPRODUCT(E2:E17,$C$2:$C$17) -> 523.352 | F19: =SUMPRODUCT(F2:F17,$C$2:$C$17) -> 401.42 | G19: =SUMPRODUCT(G2:G17,$C$2:$C$17) -> 765.012 | H19: =SUMPRODUCT(H2:H17,$C$2:$C$17) -> 424.208 | I19: =SUMPRODUCT(I2:I17,$C$2:$C$17) -> 358.372
A20: Total species counted | D20: =COUNT(D2:D17) -> 12 | E20: =COUNT(E2:E17) -> 10 | F20: =COUNT(F2:F17) -> 10 | G20: =COUNT(G2:G17) -> 11 | H20: =COUNT(H2:H17) -> 7 | I20: =COUNT(I2:I17) -> 7
D22: =D19/13300 -> 0.12216241 | E22: =E19/13300 -> 0.039349774 | F22: =F19/13300 -> 0.030181955 | G22: =G19/13300 -> 0.057519699 | H22: =H19/13300 -> 0.031895338 | I22: =I19/13300 -> 0.026945263
A24: markup | D24: 1.7 | E24: =D24 -> 1.7 | F24: =E24 -> 1.7 | G24: =F24 -> 1.7 | H24: =G24 -> 1.7 | I24: =H24 -> 1.7
D26: =D22*D24 -> 0.20767609 | E26: =E22*E24 -> 0.066894617 | F26: =F22*F24 -> 0.051309323 | G26: =G22*G24 -> 0.097783489 | H26: =H22*H24 -> 0.054222075 | I26: =I22*I24 -> 0.045806947 | N26: Mean | O26: =AVERAGE(D26:I26) -> 0.08728209

Sheet Graze_density_all
B1: Herbivores | C1: Cattle -- ambient | D1: Cattle - boma predicted | E1: Total AU
A2: 2019 | B2: =AVERAGE($B$5:$B$7) -> 0.11411411 | C2: 0.5 | D2: 0 | E2: =SUM(B2:D2) -> 0.61411411
A3: 2020 | B3: =AVERAGE($B$5:$B$7) -> 0.11411411 | C3: 0.5 | D3: 0 | E3: =SUM(B3:D3) -> 0.61411411
A4: 2021 | B4: =AVERAGE($B$5:$B$7) -> 0.11411411 | C4: 0.5 | D4: 0 | E4: =SUM(B4:D4) -> 0.61411411
A5: 2022 | B5: =Wild_herbivores!D26 -> 0.20767609 | C5: 0.5 | D5: 5 | E5: =SUM(B5:D5) -> 5.7076761
A6: 2023 | B6: =AVERAGE(Wild_herbivores!E26,Wild_herbivores!E26) -> 0.066894617 | C6: 0.5 | D6: 0 | E6: =SUM(B6:D6) -> 0.56689462
A7: 2024 | B7: =AVERAGE(Wild_herbivores!F26,Wild_herbivores!G26,Wild_herbivores!H26) -> 0.067771629 | C7: 0.5 | D7: 0 | E7: =SUM(B7:D7) -> 0.56777163
A8: 2025 | B8: =AVERAGE(B5:B7) -> 0.11411411 | C8: 0.5 | D8: 0 | E8: =SUM(B8:D8) -> 0.61411411

Sheet Calibratin parameters
E1: notes
B2: BY_PASSF | C2: 1
B3: FRUNOFF | C3: 0.05
B4: FPERCOL | C4: 0.1
B7: Parameters to calibrate
A12: Water use | B12: WUE
B13: GSMAX | E13: key determinant
A15: Photosynthesis | B15: SLA
B16: MFOLOP
A18: Phenology | B18: ND Flush
B19: ND Morta

Sheet Species_parameters
A1: No | B1: Variable | C1: Unit | E1: ANGA.JABER | F1: PERG.DEFAULT | G1: CEBI.default | I1: PERG.HYBRID.BG | L1: THEMEDA TRIANDRA
A2: 1 | B2: C4_TYPE | E2: true | I2: =F2 -> 0
A3: 2 | I3: =F3 -> 0
A4: 3 | I4: =F4 -> 0
A5: 4 | B5: FREEGROWTH | E5: true | I5: =F5 -> 0
A6: 5 | B6: RATOON | E6: false | I6: =F6 -> 0
A7: 6 | I7: =F7 -> 0
A8: 7 | B8: SAVANNA | E8: true | I8: =F8 -> 0
A9: 8 | B9: TUBER | E9: false | I9: =F9 -> 0
B11: CO2 dynamics
B13: AEJM | E13: 77900 | F13: 60650
B14: AEKC | E14: 64200 | F14: 80990
B19: KM20 | D19: aintenance coefficient at reference temperature | I19: 0.8
B20: KO25 | D20: Michaelis-Menten constant for O2 at 25oC (mmol mol-1 mbar-1). | I20: 179
B22: Lignin value | I22: 0.07
B24: MFOLOPT | I24: 0.5
B26: BIOMASS
B27: QRF | D27: Ratio between fine root- and foliage biomass under standard conditions | I27: 2.25
B28: QJVC | I28: 2
B29: PSNTOPT | I29: 25
I31: =F31 -> 0
B32: Water Balance | I32: =F33 -> 375
B33: GSMAX | D33: Maximum rate of water vapor and CO2 exchange through stomata | E33: 230 | F33: 375 | G33: 230 | I33: 600
B34: GSMIN | D34: Minimum rate of water vapor and CO2 exchange through stoma | E34: 230 | F34: 2.66 | G34: 10.4 | I34: 300
I35: =F35 -> 0
I36: =F36 -> 0
B37: SLOPE_GSA | E37: 4 | F37: 10.4 | I37: =F37 -> 10.4
I38: =F38 -> 0
B39: MWFM | E39: =0.35/1000 -> 0.00035 | F39: =0.0005 -> 0.0005 | I39: =F39 -> 0.0005
I40: =F40 -> 0
B41: SLAMAX | D41: Specific leaf area in the shade (m2 kg-1). | E41: 10.6 | F41: 13.8 | I41: =F41 -> 13.8 | L41: 12
B42: SLAMIN | D42: Specific leaf area under full light (m2 kg-1). | E42: 10.6 | F42: 13.8 | I42: =F42 -> 13.8 | L42: 7
I43: =F43 -> 0
B44: WUECMAX | C44: mg CO2/g h2o | D44: Maximum instantaneous water use efficiency | E44: 9 | F44: 5.3 | I44: 5
B45: WUECMIN | E45: 9 | F45: 5.3 | I45: 4
I46: =F46 -> 0
I47: =F47 -> 0
I48: =F48 -> 0
I49: =F49 -> 0
B50: DLEAFSHED | E50: 320 | F50: 300 | I50: =F50 -> 300
...

Sheet Site params
H1: GEMINI link | I1: source
B2: van genuchten parameter | D2: unitless | E2: =_xlfn.CONCAT("When parameterizing the biogeochemical model Landscape DNDC, what value does the ",B2," parameter take for savannah grasslands periodically grazed by livestock in vertisol soils of the Athi-Kapiti ecosystem in East Africa? The parameter is defined as the ",C2," taking units of ",D2,"") -> When parameterizing the biogeochemical model Landscape DNDC, what value does the van genuchten parameter parameter take for savannah grasslands periodically grazed by livestock in vertisol soils of the Athi-Kapiti ecosystem in East Africa? The parameter is defined as the taking units of unitless | G2: 1.1 | H2: https://gemini.google.com/app/197f6721c634301d | I2: Lipiec, J., Usowicz, B., & Siczek, A. (2024). Fitting the van Genuchten model to the measured hydraulic parameters in soils of different genesis and texture at the regional scale. International Agrophysics, 38, 373–382. https://doi.org/10.31545/intagr/191380
B3: van genuchten parameter alpha | D3: 1/m | E3: =_xlfn.CONCAT("When parameterizing the biogeochemical model Landscape DNDC, what value does the ",B3," parameter take for savannah grasslands periodically grazed by livestock in vertisol soils of the Athi-Kapiti ecosystem in East Africa? The parameter is defined as the ",C3," taking units of ",D3,"") -> When parameterizing the biogeochemical model Landscape DNDC, what value does the van genuchten parameter alpha parameter take for savannah grasslands periodically grazed by livestock in vertisol soils of the Athi-Kapiti ecosystem in East Africa? The parameter is defined as the taking units of 1/m | G3: 1.2 | H3: https://gemini.google.com/app/5fc2606a93a9412d
B4: FRUNOFF | C4: Fraction of daily runoff from surface water | D4: meters per day | E4: =_xlfn.CONCAT("When parameterizing the biogeochemical model Landscape DNDC, what value does the ",B4," parameter take for savannah grasslands periodically grazed by livestock in vertisol soils of the Athi-Kapiti ecosystem in East Africa? The parameter is defined as the ",C4," taking units of ",D4,"") -> When parameterizing the biogeochemical model Landscape DNDC, what value does the FRUNOFF parameter take for savannah grasslands periodically grazed by livestock in vertisol soils of the Athi-Kapiti ecosystem in East Africa? The parameter is defined as the Fraction of daily runoff from surface water taking units of meters per day | G4: 0.6 | H4: https://gemini.google.com/app/0c598a444ed2a5ad
B5: FPERCOL | C5: Fraction of surface water that goes into runof | D5: liters water per day | E5: =_xlfn.CONCAT("When parameterizing the biogeochemical model Landscape DNDC, what value does the ",B5," parameter take for savannah grasslands periodically grazed by livestock in vertisol soils of the Athi-Kapiti ecosystem in East Africa? The parameter is defined as the ",C5," taking units of ",D5,"") -> When parameterizing the biogeochemical model Landscape DNDC, what value does the FPERCOL parameter take for savannah grasslands periodically grazed by livestock in vertisol soils of the Athi-Kapiti ecosystem in East Africa? The parameter is defined as the Fraction of surface water that goes into runof taking units of liters water per day | G5: 0.15 | H5: https://gemini.google.com/app/c2a92930c2a26de6
B6: CRACK_DEPTH | C6: maximum depth of cracks | D6: meters | E6: =_xlfn.CONCAT("When parameterizing the biogeochemical model Landscape DNDC, what value does the ",B6," parameter take for savannah grasslands periodically grazed by livestock in vertisol soils of the Athi-Kapiti ecosystem in East Africa? The parameter is defined as the ",C6," taking units of ",D6,"") -> When parameterizing the biogeochemical model Landscape DNDC, what value does the CRACK_DEPTH parameter take for savannah grasslands periodically grazed by livestock in vertisol soils of the Athi-Kapiti ecosystem in East Africa? The parameter is defined as the maximum depth of cracks taking units of meters | G6: 0.5 | H6: https://gemini.google.com/app/12b54f3d42cde5c1
B7: CRACK_FRACTION | C7: Fraction of water that infiltrates via cracks | D7: fraction | E7: =_xlfn.CONCAT("When parameterizing the biogeochemical model Landscape DNDC, what value does the ",B7," parameter take for savannah grasslands periodically grazed by livestock in vertisol soils of the Athi-Kapiti ecosystem in East Africa? The parameter is defined as the ",C7," taking units of ",D7,"") -> When parameterizing the biogeochemical model Landscape DNDC, what value does the CRACK_FRACTION parameter take for savannah grasslands periodically grazed by livestock in vertisol soils of the Athi-Kapiti ecosystem in East Africa? The parameter is defined as the Fraction of water that infiltrates via cracks taking units of fraction | G7: 0.5 | H7: https://gemini.google.com/app/39735c7d4984dd0f
H13: =_xlfn.CONCAT("When parameterizing the biogeochemical model Landscape DNDC, what value does the ",C13," parameter take for savannah grasslands periodically grazed by livestock in vertisol soils of the Athi-Kapiti ecosystem in East Africa? The parameter is defined as the ",D13," taking units of ",E13,"") -> When parameterizing the biogeochemical model Landscape DNDC, what value does the parameter take for savannah grasslands periodically grazed by livestock in vertisol soils of the Athi-Kapiti ecosystem in East Africa? The parameter is defined as the taking units of

Sheet Lresources_WAVG
I1: wagv
B2: species.PERG.mnemonic = "PERG" | D2: species.COWP.mnemonic = "COWP" | F2: species.SORG.mnemonic = "SORG"
B3: species.PERG.group = "grass" | D3: species.COWP.group = "crop" | F3: species.SORG.group = "crop"
B4: species.PERG.parent = ":C3:" | D4: species.COWP.parent = ":LEGUME:" | F4: species.SORG.parent = ":MILLETS:"
B5: species.PERG.parameter.C4_TYPE.value = "false" | D5: species.COWP.parameter.C4_TYPE.value = "false" | F5: species.SORG.parameter.C4_TYPE.value = "true" | H5: 0.75
B6: species.PERG.parameter.CONIFEROUS.value = "false" | D6: species.COWP.parameter.CONIFEROUS.value = "false" | F6: species.SORG.parameter.CONIFEROUS.value = "false" | H6: 0.2
B7: species.PERG.parameter.DECIDUOUS.value = "true" | D7: species.COWP.parameter.DECIDUOUS.value = "true" | F7: species.SORG.parameter.DECIDUOUS.value = "true" | H7: 0.05
B8: species.PERG.parameter.FREEGROWTH.value = "true" | D8: species.COWP.parameter.FREEGROWTH.value = "true" | F8: species.SORG.parameter.FREEGROWTH.value = "true"
B9: species.PERG.parameter.RATOON.value = "false" | D9: species.COWP.parameter.RATOON.value = "false" | F9: species.SORG.parameter.RATOON.value = "false"
B10: species.PERG.parameter.ROOTS_ENVIRONMENTAL.value = "false" | D10: species.COWP.parameter.ROOTS_ENVIRONMENTAL.value = "false" | F10: species.SORG.parameter.ROOTS_ENVIRONMENTAL.value = "false"
B11: species.PERG.parameter.SAVANNA.value = "false" | D11: species.COWP.parameter.SAVANNA.value = "false" | F11: species.SORG.parameter.SAVANNA.value = "false"
B12: species.PERG.parameter.TUBER.value = "true" | D12: species.COWP.parameter.TUBER.value = "false" | F12: species.SORG.parameter.TUBER.value = "false"
A13: AEIS | B13: species.PERG.parameter.AEIS.value = "0" | D13: species.COWP.parameter.AEIS.value = "0" | E13: 0 | F13: species.SORG.parameter.AEIS.value = "0" | G13: 0 | I13: =C13*$H$5+E13*$H$6+G13*$H$7 -> 0
A14: AEJM | B14: species.PERG.parameter.AEJM.value = "60650" | C14: 40000 | D14: species.COWP.parameter.AEJM.value = "45000" | E14: 45000 | F14: species.SORG.parameter.AEJM.value = "77900" | G14: 77900 | I14: =C14*$H$5+E14*$H$6+G14*$H$7 -> 42895
A15: AEKC | B15: species.PERG.parameter.AEKC.value = "80990" | C15: 36300 | D15: species.COWP.parameter.AEKC.value = "59356" | E15: 59356 | F15: species.SORG.parameter.AEKC.value = "59356" | G15: 59356 | I15: =C15*$H$5+E15*$H$6+G15*$H$7 -> 42064
A16: AEKO | B16: species.PERG.parameter.AEKO.value = "23720" | C16: 70000 | D16: species.COWP.parameter.AEKO.value = "35948" | E16: 35948 | F16: species.SORG.parameter.AEKO.value = "36000" | G16: 36000 | I16: =C16*$H$5+E16*$H$6+G16*$H$7 -> 61489.6
A17: AERD | B17: species.PERG.parameter.AERD.value = "46390" | C17: 60000 | D17: species.COWP.parameter.AERD.value = "66405" | E17: 66405 | F17: species.SORG.parameter.AERD.value = "50967" | G17: 50967 | I17: =C17*$H$5+E17*$H$6+G17*$H$7 -> 60829.35
A18: AEVC | B18: species.PERG.parameter.AEVC.value = "65330" | C18: 65330 | D18: species.COWP.parameter.AEVC.value = "58520" | E18: 58520 | F18: species.SORG.parameter.AEVC.value = "36000" | G18: 36000 | I18: =C18*$H$5+E18*$H$6+G18*$H$7 -> 62501.5
A19: AEVO | B19: species.PERG.parameter.AEVO.value = "37530" | C19: 37530 | D19: species.COWP.parameter.AEVO.value = "37530" | E19: 37530 | F19: species.SORG.parameter.AEVO.value = "55300" | G19: 55300 | I19: =C19*$H$5+E19*$H$6+G19*$H$7 -> 38418.5
A20: ALB | B20: species.PERG.parameter.ALB.value = "0.12" | C20: 0.12 | D20: species.COWP.parameter.ALB.value = "0.19" | E20: 0.19 | F20: species.SORG.parameter.ALB.value = "0.19" | G20: 0.19 | I20: =C20*$H$5+E20*$H$6+G20*$H$7 -> 0.1375
A21: A | B21: species.PERG.parameter.ALPHA0_IS.value = "0" | C21: 0 | D21: species.COWP.parameter.ALPHA0_IS.value = "0" | E21: 0 | F21: species.SORG.parameter.ALPHA0_IS.value = "0" | G21: 0 | I21: =C21*$H$5+E21*$H$6+G21*$H$7 -> 0
A22: ALPHA0_MT | B22: species.PERG.parameter.ALPHA0_MT.value = "0" | C22: 0 | D22: species.COWP.parameter.ALPHA0_MT.value = "0" | E22: 0 | F22: species.SORG.parameter.ALPHA0_MT.value = "0" | G22: 0 | I22: =C22*$H$5+E22*$H$6+G22*$H$7 -> 0
A23: AMAXA | B23: species.PERG.parameter.AMAXA.value = "5.3" | C23: 5.3 | D23: species.COWP.parameter.AMAXA.value = "5.3" | E23: 5.3 | F23: species.SORG.parameter.AMAXA.value = "5.3" | G23: 5.3 | I23: =C23*$H$5+E23*$H$6+G23*$H$7 -> 5.3
A24: value = "21 | B24: species.PERG.parameter.AMAXB.value = "21.5" | C24: 21.5 | D24: species.COWP.parameter.AMAXB.value = "21.5" | E24: 21.5 | F24: species.SORG.parameter.AMAXB.value = "21.5" | G24: 21.5 | I24: =C24*$H$5+E24*$H$6+G24*$H$7 -> 21.5
A25: value = "0 | B25: species.PERG.parameter.AMAXFRAC.value = "0.76" | C25: 0.76 | D25: species.COWP.parameter.AMAXFRAC.value = "0.76" | E25: 0.76 | F25: species.SORG.parameter.AMAXFRAC.value = "0.76" | G25: 0.76 | I25: =C25*$H$5+E25*$H$6+G25*$H$7 -> 0.76
... A247: NDMORTA | B247: species.PERG.parameter.NDMORTA.value = "150" | C247: 35 | D247: species.COWP.parameter.NDMORTA.value = "40" | E247: 40 | F247: species.SORG.parameter.NDMORTA.value = "40" | G247: 40 | I247: =C247*$H$5+E247*$H$6+G247*$H$7 -> 36.25

Sheet Params_specs_ALL
B1: Lresources entry no | C1: Category | D1: Description | E1: unit, words | F1: unit, technical | G1: GRASS SPECIES | H1: Cenchrus ciliaris | I1: Point_estimate | J1: Min | K1: Max | L1: Midpoint | M1: Species | N1: Common name | O1: Search text | P1: citation | Q1: Google gemini link | S1: Species 2 - common name | T1: Species 2 - scientific name | U1: Range_min | V1: Range_max | W1: Estimated middle | X1: Search text | Y1: citation | Z1: Google gemini link | AA1: Species 3 - common name | AB1: Species 2 - scientific name | AC1: =U1 -> Range_min | AD1: =V1 -> Range_max | AE1: =W1 -> Estimated middle | AF1: =X1 -> Search text | AG1: =Y1 -> citation | AH1: =Z1 -> Google gemini link | AJ1: GRASS.HYBRID.1 | AK1: GRASS.HYBRID.2 | AL1: GRASS.HYBRID.3 | AM1: GRASS.HYBRID.4 | AN1: hybrid.include | AO1: Weights | AP1: hybrid.1 | AQ1: hybrid.2 | AR1: hybrid.3 | AS1: hybrid.4 | AT1: hybrid.1 | AU1: Woody species | AV1: =S1 -> Species 2 - common name | AW1: Family | AX1: Tribe | AY1: =T1 -> Species 2 - scientific name | AZ1: =U1 -> Range_min | BA1: =V1 -> Range_max | BB1: Middle | BC1: =X1 -> Search text | BD1: =Y1 -> citation | BE1: =Z1 -> Google gemini link | BF1: =AA1 -> Species 3 - common name | BG1: Forbs | BH1: Species 1 - common name | BI1: examples | BJ1: =AY1 -> Species 2 - scientific name | BK1: =AZ1 -> Range_min | BL1: =BA1 -> Range_max | BM1: =#REF! -> #REF! | BN1: =BC1 -> Search text | BO1: =BD1 -> citation | BP1: =BE1 -> Google gemini link | BR1: Species 2 - common name | BS1: examples | BT1: =BI1 -> examples | BU1: =BJ1 -> Species 2 - scientific name | BV1: =BK1 -> Range_min | BW1: =BL1 -> Range_max | BX1: =BM1 -> #REF! | BY1: =BN1 -> Search text | BZ1: =BO1 -> citation | CA1: Gemini link | CC1: FORB.HYBRID.1 | CD1: FORB.HYBRID.2 | CE1: FORB.HYBRID.3 | CF1: FORB.HYBRID.4 | CG1: weights | CH1: 1 | CI1: 2 | CJ1: 3 | CK1: 4
A2: KO25 | C2: Gas exchange | D2: Michaelis–Menten constant for O2 at 25◦C | E2: micromols per mol per mbar | F2: µmol mol^−1 mbar^-1 | J2: 400 | K2: 550 | L2: =J2+(K2-J2)*0.5 -> 475 | M2: Cenchrus grass species | N2: Cenchrus ciliaris, Cenchrus purpureus, Cenchrus setiger, Cenchrus setaceus, Cenchrus biflorus, Cenchrus Mezianus | O2: =_xlfn.CONCAT("studies which report the ",D2," as ",E2," (",F2,") , and the values reported therein, of ",M2, " (",N2, ") under semi-arid environments. Provide the links to the scientific article") -> studies which report the Michaelis–Menten constant for O2 at 25◦C as micromols per mol per mbar ( µmol mol^−1 mbar^-1) , and the values reported therein, of Cenchrus grass species (Cenchrus ciliaris, Cenchrus purpureus, Cenchrus setiger, Cenchrus setaceus, Cenchrus biflorus, Cenchrus Mezianus ) under semi-arid environments. Provide the links to the scientific article | Q2: https://gemini.google.com/app/c7066ed2c53b6e7c | S2: red oat grass | T2: Themeda triandra | W2: 450 | X2: =_xlfn.CONCAT("studies which report the ",D2," as ",E2," (",F2,") , and the values reported therein, of ",S2, " (",T2, ") under semi-arid environments. Provide the links to the scientific article") -> studies which report the Michaelis–Menten constant for O2 at 25◦C as micromols per mol per mbar ( µmol mol^−1 mbar^-1) , and the values reported therein, of red oat grass (Themeda triandra) under semi-arid environments. Provide the links to the scientific article | Y2: von Caemmerer, S. (2000). Biochemical Models of Leaf Photosynthesis. CSIRO Publishing. | Z2: https://gemini.google.com/app/ec0e8322c79c3a7d | AA2: bermuda grass | AB2: cynodon dactylon | AD2: 450 | AE2: 450 | AF2: =_xlfn.CONCAT("studies which report the ",D2," as ",E2," (",F2,") , and the values reported therein, of ",AA2, " (",AB2, ") under semi-arid environments. Provide the links to the scientific article") -> studies which report the Michaelis–Menten constant for O2 at 25◦C as micromols per mol per mbar ( µmol mol^−1 mbar^-1) , and the values reported therein, of bermuda grass (cynodon dactylon) under semi-arid environments. Provide the links to the scientific article | AH2: https://gemini.google.com/app/0ef4ec208864b341 | AI2: =$L2*AO$2+$W2*AO$3 -> 345 | AJ2: =$L2*AO$2+$W2*AO$3+$AE2*AO$4 -> 457.5 | AK2: =$L2*AP$2+$W2*AP$3+$AE2*AP$4 -> 460 | AL2: =$L2*AQ$2+$W2*AQ$3+$AE2*AQ$4 -> 460 | AM2: =$L2*AR$2+$W2*AR$3+$AE2*AR$4 -> 457.5 | AN2: Buffel grass | AO2: 0.3 | AP2: 0.4 | AQ2: 0.4 | AR2: 0.3 | AU2: Whistling thorn | AV2: Vachellia drepanolobium | AW2: Mimosoideae | AX2: Acacieae | BC2: =_xlfn.CONCAT("studies which report the ",D2," as ",E2," (",F2,") , and the values reported therein, of ",ABX2, " (",AV2, ") under semi-arid environments. Provide the links to the scientific article") -> studies which report the Michaelis–Menten constant for O2 at 25◦C as micromols per mol per mbar ( µmol mol^−1 mbar^-1) , and the values reported therein, of (Vachellia drepanolobium) under semi-arid environments. Provide the links to the scientific article | BG2: indigofera | BH2: Indigofera voharamensis, indigofera volkensii | BM2: =_xlfn.CONCAT("studies which report the ",D2," as ",E2," (",F2,") , and the values reported therein of ",BG2," genus vegetation (e.g. ",BH2," ). Provide the links to the scientific article") -> studies which report the Michaelis–Menten constant for O2 at 25◦C as micromols per mol per mbar ( µmol mol^−1 mbar^-1) , and the values reported therein of indigofera genus vegetation (e.g. Indigofera voharamensis, indigofera volkensii ). Provide the links to the scientific article | BQ2: tephrosia | BR2: tephrosia elata | BW2: 0.5 | BX2: =_xlfn.CONCAT("studies which report the ",D2," as ",E2," (",F2,") , and the values reported therein of ",BQ2," genus vegetation (e.g. ",BR2," ). Provide the links to the scientific article") -> studies which report the Michaelis–Menten constant for O2 at 25◦C as micromols per mol per mbar ( µmol mol^−1 mbar^-1) , and the values reported therein of tephrosia genus vegetation (e.g. tephrosia elata ). Provide the links to the scientific article | CB2: =$BL2*CG$2+$BW2*CG$3 -> 0.3 | CC2: =$BL2*CH$2+$BW2*CH$3 -> 0.25 | CD2: =$BL2*CI$2+$BW2*CI$3 -> 0.2 | CE2: =$BL2*CJ$2+$BW2*CJ$3 -> 0.15 | CF2: indigofera | CG2: 0.4 | CH2: 0.5 | CI2: 0.6 | CJ2: 0.7
