Workbook

Sheet Summary
A1: year | C1: Temp.max | D1: Temp.min | E1: Temp.avg | F1: Precip | G1: Relative.humid | H1: Wind.speed | I1: Radiation
A2: 2010 | B2: 1 | C2: =[1]data!A1 -> 15.73 | D2: =[2]data!A1 -> 8.89 | E2: =[3]data!A1 -> 12.1 | F2: =[4]data!A1 -> 0.01 | G2: =[5]data!A1 -> 66.53 | H2: =[6]data!A1 -> 4.99 | I2: =[7]data!A1 -> 9.92
A3: 2010 | B3: 2 | C3: =[1]data!A2 -> 15.41 | D3: =[2]data!A2 -> 9.29 | E3: =[3]data!A2 -> 12.15 | F3: =[4]data!A2 -> 0 | G3: =[5]data!A2 -> 74.22 | H3: =[6]data!A2 -> 1.72 | I3: =[7]data!A2 -> 9.96
A4: 2010 | B4: 3 | C4: =[1]data!A3 -> 15.3 | D4: =[2]data!A3 -> 10.32 | E4: =[3]data!A3 -> 12.49 | F4: =[4]data!A3 -> 0.07 | G4: =[5]data!A3 -> 84.45 | H4: =[6]data!A3 -> 2.29 | I4: =[7]data!A3 -> 8.23
A5: 2010 | B5: 4 | C5: =[1]data!A4 -> 16.76 | D5: =[2]data!A4 -> 12.42 | E5: =[3]data!A4 -> 13.98 | F5: =[4]data!A4 -> 1.67 | G5: =[5]data!A4 -> 87.71 | H5: =[6]data!A4 -> 3.4 | I5: =[7]data!A4 -> 5.32
A6: 2010 | B6: 5 | C6: =[1]data!A5 -> 16.83 | D6: =[2]data!A5 -> 11.86 | E6: =[3]data!A5 -> 13.89 | F6: =[4]data!A5 -> 11.07 | G6: =[5]data!A5 -> 79.37 | H6: =[6]data!A5 -> 5.33 | I6: =[7]data!A5 -> 7.33
A7: 2010 | B7: 6 | C7: =[1]data!A6 -> 15.64 | D7: =[2]data!A6 -> 9.98 | E7: =[3]data!A6 -> 12.68 | F7: =[4]data!A6 -> 0.08 | G7: =[5]data!A6 -> 70.89 | H7: =[6]data!A6 -> 3.21 | I7: =[7]data!A6 -> 6.86
A8: 2010 | B8: 7 | C8: =[1]data!A7 -> 13.35 | D8: =[2]data!A7 -> 8.1 | E8: =[3]data!A7 -> 11.54 | F8: =[4]data!A7 -> 24.28 | G8: =[5]data!A7 -> 86.13 | H8: =[6]data!A7 -> 3.83 | I8: =[7]data!A7 -> 2.05
A9: 2010 | B9: 8 | C9: =[1]data!A8 -> 9.17 | D9: =[2]data!A8 -> 4.99 | E9: =[3]data!A8 -> 6.82 | F9: =[4]data!A8 -> 0.17 | G9: =[5]data!A8 -> 63.38 | H9: =[6]data!A8 -> 6.49 | I9: =[7]data!A8 -> 6.84
A10: 2010 | B10: 9 | C10: =[1]data!A9 -> 10.24 | D10: =[2]data!A9 -> 3.21 | E10: =[3]data!A9 -> 6.05 | F10: =[4]data!A9 -> 0 | G10: =[5]data!A9 -> 58.84 | H10: =[6]data!A9 -> 4.08 | I10: =[7]data!A9 -> 11.04
A11: 2010 | B11: 10 | C11: =[1]data!A10 -> 10.44 | D11: =[2]data!A10 -> 4.43 | E11: =[3]data!A10 -> 7.02 | F11: =[4]data!A10 -> 2.13 | G11: =[5]data!A10 -> 63 | H11: =[6]data!A10 -> 1.35 | I11: =[7]data!A10 -> 7.32
A12: 2010 | B12: 11 | C12: =[1]data!A11 -> 15.94 | D12: =[2]data!A11 -> 7.44 | E12: =[3]data!A11 -> 11 | F12: =[4]data!A11 -> 0.32 | G12: =[5]data!A11 -> 83.73 | H12: =[6]data!A11 -> 2.95 | I12: =[7]data!A11 -> 7.48
A13: 2010 | B13: 12 | C13: =[1]data!A12 -> 14.57 | D13: =[2]data!A12 -> 8.63 | E13: =[3]data!A12 -> 12.12 | F13: =[4]data!A12 -> 1.18 | G13: =[5]data!A12 -> 85.45 | H13: =[6]data!A12 -> 5.13 | I13: =[7]data!A12 -> 2.46
... A366: 2010 | B366: 365 | C366: =[1]data!A365 -> 13.85 | D366: =[2]data!A365 -> 11.08 | E366: =[3]data!A365 -> 12.36 | F366: =[4]data!A365 -> 5.76 | G366: =[5]data!A365 -> 89.99 | H366: =[6]data!A365 -> 1.4 | I366: =[7]data!A365 -> 7.46
A367: 2011 | B367: 1 | C367: =[8]data!A1 -> 16.84 | D367: =[9]data!A1 -> 10.24 | E367: =[10]data!A1 -> 13.03 | F367: =[11]data!A1 -> 2.48 | G367: =[12]data!A1 -> 82.78 | H367: =[13]data!A1 -> 1.78 | I367: =[14]data!A1 -> 6.45
A368: 2011 | B368: 2 | C368: =[8]data!A2 -> 16.56 | D368: =[9]data!A2 -> 9.77 | E368: =[10]data!A2 -> 12.53 | F368: =[11]data!A2 -> 0.47 | G368: =[12]data!A2 -> 75.44 | H368: =[13]data!A2 -> 2.46 | I368: =[14]data!A2 -> 7.89
A369: 2011 | B369: 3 | C369: =[8]data!A3 -> 15.32 | D369: =[9]data!A3 -> 8.43 | E369: =[10]data!A3 -> 11.4 | F369: =[11]data!A3 -> 0 | G369: =[12]data!A3 -> 74.11 | H369: =[13]data!A3 -> 2.41 | I369: =[14]data!A3 -> 10.55
A370: 2011 | B370: 4 | C370: =[8]data!A4 -> 15.12 | D370: =[9]data!A4 -> 8.22 | E370: =[10]data!A4 -> 11.46 | F370: =[11]data!A4 -> 0 | G370: =[12]data!A4 -> 78.86 | H370: =[13]data!A4 -> 1.89 | I370: =[14]data!A4 -> 9.14
A371: 2011 | B371: 5 | C371: =[8]data!A5 -> 17.01 | D371: =[9]data!A5 -> 9.33 | E371: =[10]data!A5 -> 12.54 | F371: =[11]data!A5 -> 0 | G371: =[12]data!A5 -> 81.91 | H371: =[13]data!A5 -> 2.63 | I371: =[14]data!A5 -> 8.43
A372: 2011 | B372: 6 | C372: =[8]data!A6 -> 18.05 | D372: =[9]data!A6 -> 11.13 | E372: =[10]data!A6 -> 13.87 | F372: =[11]data!A6 -> 0 | G372: =[12]data!A6 -> 87.85 | H372: =[13]data!A6 -> 3.5 | I372: =[14]data!A6 -> 9.48
A373: 2011 | B373: 7 | C373: =[8]data!A7 -> 17.16 | D373: =[9]data!A7 -> 11.47 | E373: =[10]data!A7 -> 13.81 | F373: =[11]data!A7 -> 0.03 | G373: =[12]data!A7 -> 80.96 | H373: =[13]data!A7 -> 3.44 | I373: =[14]data!A7 -> 6.52
A374: 2011 | B374: 8 | C374: =[8]data!A8 -> 17.49 | D374: =[9]data!A8 -> 12.27 | E374: =[10]data!A8 -> 14.07 | F374: =[11]data!A8 -> 0 | G374: =[12]data!A8 -> 83 | H374: =[13]data!A8 -> 1.82 | I374: =[14]data!A8 -> 10.28
A375: 2011 | B375: 9 | C375: =[8]data!A9 -> 16.48 | D375: =[9]data!A9 -> 11.35 | E375: =[10]data!A9 -> 13.44 | F375: =[11]data!A9 -> 0.15 | G375: =[12]data!A9 -> 77.36 | H375: =[13]data!A9 -> 3.7 | I375: =[14]data!A9 -> 6.36
A376: 2011 | B376: 10 | C376: =[8]data!A10 -> 15.87 | D376: =[9]data!A10 -> 8.91 | E376: =[10]data!A10 -> 11.81 | F376: =[11]data!A10 -> 0.05 | G376: =[12]data!A10 -> 66.81 | H376: =[13]data!A10 -> 2.42 | I376: =[14]data!A10 -> 11.18
A377: 2011 | B377: 11 | C377: =[8]data!A11 -> 17.99 | D377: =[9]data!A11 -> 9.05 | E377: =[10]data!A11 -> 12.71 | F377: =[11]data!A11 -> 0 | G377: =[12]data!A11 -> 73.42 | H377: =[13]data!A11 -> 2.62 | I377: =[14]data!A11 -> 9.17
A378: 2011 | B378: 12 | C378: =[8]data!A12 -> 18.35 | D378: =[9]data!A12 -> 10.5 | E378: =[10]data!A12 -> 13.74 | F378: =[11]data!A12 -> 0 | G378: =[12]data!A12 -> 75.1 | H378: =[13]data!A12 -> 2.77 | I378: =[14]data!A12 -> 10.81
... A731: 2011 | B731: 365 | C731: =[8]data!A365 -> 18.35 | D731: =[9]data!A365 -> 9.34 | E731: =[10]data!A365 -> 13.44 | F731: =[11]data!A365 -> 0 | G731: =[12]data!A365 -> 61.51 | H731: =[13]data!A365 -> 2.19 | I731: =[14]data!A365 -> 10.44
A732: 2012 | B732: 1 | C732: =[15]data!A1 -> 18.56 | D732: =[16]data!A1 -> 11.91 | E732: =[17]data!A1 -> 14.35 | F732: =[18]data!A1 -> 0 | G732: =[19]data!A1 -> 68.66 | H732: =[20]data!A1 -> 2.66 | I732: =[21]data!A1 -> 10.49
A733: 2012 | B733: 2 | C733: =[15]data!A2 -> 17.62 | D733: =[16]data!A2 -> 10.52 | E733: =[17]data!A2 -> 13.2 | F733: =[18]data!A2 -> 0 | G733: =[19]data!A2 -> 71.4 | H733: =[20]data!A2 -> 2.74 | I733: =[21]data!A2 -> 10.17
A734: 2012 | B734: 3 | C734: =[15]data!A3 -> 17.42 | D734: =[16]data!A3 -> 9.42 | E734: =[17]data!A3 -> 12.54 | F734: =[18]data!A3 -> 0 | G734: =[19]data!A3 -> 67.68 | H734: =[20]data!A3 -> 2.34 | I734: =[21]data!A3 -> 10.78
A735: 2012 | B735: 4 | C735: =[15]data!A4 -> 18.14 | D735: =[16]data!A4 -> 10.02 | E735: =[17]data!A4 -> 13.21 | F735: =[18]data!A4 -> 0 | G735: =[19]data!A4 -> 61.81 | H735: =[20]data!A4 -> 1.7 | I735: =[21]data!A4 -> 11.26
A736: 2012 | B736: 5 | C736: =[15]data!A5 -> 20.08 | D736: =[16]data!A5 -> 11.12 | E736: =[17]data!A5 -> 14.37 | F736: =[18]data!A5 -> 0 | G736: =[19]data!A5 -> 58.9 | H736: =[20]data!A5 -> 3.06 | I736: =[21]data!A5 -> 11.12
A737: 2012 | B737: 6 | C737: =[15]data!A6 -> 21.1 | D737: =[16]data!A6 -> 11.78 | E737: =[17]data!A6 -> 15.13 | F737: =[18]data!A6 -> 0 | G737: =[19]data!A6 -> 60.89 | H737: =[20]data!A6 -> 2.35 | I737: =[21]data!A6 -> 8.84
A738: 2012 | B738: 7 | C738: =[15]data!A7 -> 15.5 | D738: =[16]data!A7 -> 12 | E738: =[17]data!A7 -> 13.22 | F738: =[18]data!A7 -> 0 | G738: =[19]data!A7 -> 81.52 | H738: =[20]data!A7 -> 2.66 | I738: =[21]data!A7 -> 10.03
A739: 2012 | B739: 8 | C739: =[15]data!A8 -> 14.93 | D739: =[16]data!A8 -> 9.86 | E739: =[17]data!A8 -> 12.03 | F739: =[18]data!A8 -> 0 | G739: =[19]data!A8 -> 73.17 | H739: =[20]data!A8 -> 2.19 | I739: =[21]data!A8 -> 11.05
A740: 2012 | B740: 9 | C740: =[15]data!A9 -> 14.86 | D740: =[16]data!A9 -> 9.63 | E740: =[17]data!A9 -> 11.57 | F740: =[18]data!A9 -> 0 | G740: =[19]data!A9 -> 72.38 | H740: =[20]data!A9 -> 3.09 | I740: =[21]data!A9 -> 10.52
A741: 2012 | B741: 10 | C741: =[15]data!A10 -> 13.8 | D741: =[16]data!A10 -> 9.82 | E741: =[17]data!A10 -> 11.85 | F741: =[18]data!A10 -> 0 | G741: =[19]data!A10 -> 82.71 | H741: =[20]data!A10 -> 4.16 | I741: =[21]data!A10 -> 8.42
A742: 2012 | B742: 11 | C742: =[15]data!A11 -> 14.29 | D742: =[16]data!A11 -> 9 | E742: =[17]data!A11 -> 11.59 | F742: =[18]data!A11 -> 0 | G742: =[19]data!A11 -> 84.51 | H742: =[20]data!A11 -> 4.44 | I742: =[21]data!A11 -> 7.07
A743: 2012 | B743: 12 | C743: =[15]data!A12 -> 14.38 | D743: =[16]data!A12 -> 10.83 | E743: =[17]data!A12 -> 12.18 | F743: =[18]data!A12 -> 0 | G743: =[19]data!A12 -> 78.55 | H743: =[20]data!A12 -> 3.81 | I743: =[21]data!A12 -> 8.01
... A1097: 2012 | B1097: 366 | C1097: =[15]data!A366 -> 13.96 | D1097: =[16]data!A366 -> 8.63 | E1097: =[17]data!A366 -> 10.95 | F1097: =[18]data!A366 -> 0 | G1097: =[19]data!A366 -> 74.23 | H1097: =[20]data!A366 -> 2.16 | I1097: =[21]data!A366 -> 8.45
...

Sheet Sheet4
A2: 1980 | B2: 1 | C2: 19.25 | D2: 14.12 | E2: 24.18 | F2: 280.23 | G2: 0 | H2: 62.72 | I2: 4.63
A3: 1980 | B3: 2 | C3: 17.98 | D3: 13.75 | E3: 23.01 | F3: 211.09 | G3: 0.1 | H3: 72.71 | I3: 4.88
A4: 1980 | B4: 3 | C4: 17.25 | D4: 15.45 | E4: 20.82 | F4: 214.32 | G4: 10.62 | H4: 87.78 | I4: 5.48
A5: 1980 | B5: 4 | C5: 16.94 | D5: 15.21 | E5: 19.18 | F5: 103.83 | G5: 4.8 | H5: 89.25 | I5: 4.65
A6: 1980 | B6: 5 | C6: 17.62 | D6: 14.54 | E6: 21.55 | F6: 274.51 | G6: 0.2 | H6: 77.42 | I6: 4.38
A7: 1980 | B7: 6 | C7: 19.42 | D7: 13.57 | E7: 24.66 | F7: 376.05 | G7: 0 | H7: 56.91 | I7: 3.87
A8: 1980 | B8: 7 | C8: 19.6 | D8: 14.23 | E8: 24.56 | F8: 355.46 | G8: 0 | H8: 60.44 | I8: 4.2
A9: 1980 | B9: 8 | C9: 19.01 | D9: 13.81 | E9: 24.6 | F9: 361.29 | G9: 0 | H9: 73.27 | I9: 4.48
A10: 1980 | B10: 9 | C10: 19.48 | D10: 16.27 | E10: 24.33 | F10: 277.82 | G10: 0 | H10: 74.98 | I10: 5.09
A11: 1980 | B11: 10 | C11: 19.17 | D11: 15.9 | E11: 23.54 | F11: 312.8 | G11: 0 | H11: 73.78 | I11: 4.69
A12: 1980 | B12: 11 | C12: 19.18 | D12: 14.34 | E12: 24.06 | F12: 300.67 | G12: 0 | H12: 70.07 | I12: 4.13
A13: 1980 | B13: 12 | C13: 19.84 | D13: 14.59 | E13: 25.32 | F13: 365.58 | G13: 0 | H13: 64.35 | I13: 4.95
... A366: 1980 | B366: 365 | C366: 20.6 | D366: 17.19 | E366: 25.44 | F366: 386.32 | G366: 0 | H366: 78.05 | I366: 2.63

Sheet Pastable
A1: * | B1: * | C1: tavg | D1: tmin | E1: tmax | F1: grad | G1: prec | H1: rh | I1: wind
M2: MJ to Watts | N2: 11.57
M3: Mean bias Tavg | N3: 0.99 | O3: 0.99
M4: Mean bias Tmin | N4: 1.593796 | O4: 1.593796
M5: Mean bias Tmax | N5: 1.089054 | O5: 1.089054
A6: 2009 | B6: 1 | C6: =Summary!#REF! -> #REF! | D6: =Summary!#REF! -> #REF! | E6: =Summary!#REF! -> #REF! | F6: 280.23 | G6: =Summary!#REF! -> #REF! | H6: 77.42 | I6: 4.38 | M6: Mean bias Radiation | N6: 1.593796 | O6: 1.593796
A7: 2009 | B7: 2 | C7: =Summary!#REF! -> #REF! | D7: =Summary!#REF! -> #REF! | E7: =Summary!#REF! -> #REF! | F7: 211.09 | H7: 56.91 | I7: 3.87 | M7: Mean bias Precip | N7: 2.809125 | O7: 2.809125
A8: 2009 | B8: 3 | C8: =Summary!#REF! -> #REF! | D8: =Summary!#REF! -> #REF! | E8: =Summary!#REF! -> #REF! | F8: 214.32 | H8: 60.44 | I8: 4.2 | M8: Mean bias Relative humidity | N8: 1.091828 | O8: 1.091828
A9: 2009 | B9: 4 | C9: =Summary!#REF! -> #REF! | D9: =Summary!#REF! -> #REF! | E9: =Summary!#REF! -> #REF! | F9: 103.83 | H9: 73.27 | I9: 4.48 | M9: Mean bias Wind speed | N9: 1.029006 | O9: 1.029006
A10: 2009 | B10: 5 | C10: =Summary!#REF! -> #REF! | D10: =Summary!#REF! -> #REF! | E10: =Summary!#REF! -> #REF! | F10: 274.51 | H10: 74.98 | I10: 5.09
A11: 2009 | B11: 6 | C11: =Summary!#REF! -> #REF! | D11: =Summary!#REF! -> #REF! | E11: =Summary!#REF! -> #REF! | F11: 376.05 | H11: 73.78 | I11: 4.69
A12: 2009 | B12: 7 | C12: =Summary!#REF! -> #REF! | D12: =Summary!#REF! -> #REF! | E12: =Summary!#REF! -> #REF! | F12: 355.46 | H12: 70.07 | I12: 4.13
A13: 2009 | B13: 8 | C13: =Summary!#REF! -> #REF! | D13: =Summary!#REF! -> #REF! | E13: =Summary!#REF! -> #REF! | F13: 361.29 | H13: 64.35 | I13: 4.95
A14: 2009 | B14: 9 | C14: =Summary!#REF! -> #REF! | D14: =Summary!#REF! -> #REF! | E14: =Summary!#REF! -> #REF! | F14: 277.82 | H14: 57.99 | I14: 4.46
A15: 2009 | B15: 10 | C15: =Summary!#REF! -> #REF! | D15: =Summary!#REF! -> #REF! | E15: =Summary!#REF! -> #REF! | F15: 312.8 | H15: 57.68 | I15: 3.85
A16: 2009 | B16: 11 | C16: =Summary!#REF! -> #REF! | D16: =Summary!#REF! -> #REF! | E16: =Summary!#REF! -> #REF! | F16: 300.67 | H16: 53.19 | I16: 4.17
A17: 2009 | B17: 12 | C17: =Summary!#REF! -> #REF! | D17: =Summary!#REF! -> #REF! | E17: =Summary!#REF! -> #REF! | F17: 365.58 | H17: 58.45 | I17: 4.01
A18: 2009 | B18: 13 | C18: =Summary!#REF! -> #REF! | D18: =Summary!#REF! -> #REF! | E18: =Summary!#REF! -> #REF! | F18: 359.62 | H18: 61.1 | I18: 4.05
A19: 2009 | B19: 14 | C19: =Summary!#REF! -> #REF! | D19: =Summary!#REF! -> #REF! | E19: =Summary!#REF! -> #REF! | F19: 341.86 | H19: 39.06 | I19: 3.88
A20: 2009 | B20: 15 | C20: =Summary!#REF! -> #REF! | D20: =Summary!#REF! -> #REF! | E20: =Summary!#REF! -> #REF! | F20: 349.03 | H20: 43.76 | I20: 3.63
A21: 2009 | B21: 16 | C21: =Summary!#REF! -> #REF! | D21: =Summary!#REF! -> #REF! | E21: =Summary!#REF! -> #REF! | F21: 347.23 | H21: 53.2 | I21: 4.18
... A370: 2009 | B370: 365 | C370: =Summary!#REF! -> #REF! | D370: =Summary!#REF! -> #REF! | E370: =Summary!#REF! -> #REF! | F370: 386.32 | H370: 73.27 | I370: 4.48
A371: 2010 | B371: 1 | C371: =Summary!E2*$N$3 -> 11.979 | D371: =Summary!D2*$N$4 -> 14.168846 | E371: =Summary!C2*$N$5 -> 17.130819 | F371: =Summary!I2*$N$6 -> 15.810456 | G371: =Summary!F2*$N$7 -> 0.02809125 | H371: =Summary!G2*$N$8 -> 72.639317 | I371: =Summary!H2*$N$9 -> 5.1347399
A372: 2010 | B372: 2 | C372: =Summary!E3*$N$3 -> 12.0285 | D372: =Summary!D3*$N$4 -> 14.806365 | E372: =Summary!C3*$N$5 -> 16.782322 | F372: =Summary!I3*$N$6 -> 15.874208 | G372: =Summary!F3*$N$7 -> 0 | H372: =Summary!G3*$N$8 -> 81.035474 | I372: =Summary!H3*$N$9 -> 1.7698903
A373: 2010 | B373: 3 | C373: =Summary!E4*$N$3 -> 12.3651 | D373: =Summary!D4*$N$4 -> 16.447975 | E373: =Summary!C4*$N$5 -> 16.662526 | F373: =Summary!I4*$N$6 -> 13.116941 | G373: =Summary!F4*$N$7 -> 0.19663875 | H373: =Summary!G4*$N$8 -> 92.204875 | I373: =Summary!H4*$N$9 -> 2.3564237
A374: 2010 | B374: 4 | C374: =Summary!E5*$N$3 -> 13.8402 | D374: =Summary!D5*$N$4 -> 19.794946 | E374: =Summary!C5*$N$5 -> 18.252545 | F374: =Summary!I5*$N$6 -> 8.4789947 | G374: =Summary!F5*$N$7 -> 4.6912387 | H374: =Summary!G5*$N$8 -> 95.764234 | I374: =Summary!H5*$N$9 -> 3.4986204
A375: 2010 | B375: 5 | C375: =Summary!E6*$N$3 -> 13.7511 | D375: =Summary!D6*$N$4 -> 18.902421 | E375: =Summary!C6*$N$5 -> 18.328779 | F375: =Summary!I6*$N$6 -> 11.682525 | G375: =Summary!F6*$N$7 -> 31.097014 | H375: =Summary!G6*$N$8 -> 86.658388 | I375: =Summary!H6*$N$9 -> 5.484602
A376: 2010 | B376: 6 | C376: =Summary!E7*$N$3 -> 12.5532 | D376: =Summary!D7*$N$4 -> 15.906084 | E376: =Summary!C7*$N$5 -> 17.032805 | F376: =Summary!I7*$N$6 -> 10.933441 | G376: =Summary!F7*$N$7 -> 0.22473 | H376: =Summary!G7*$N$8 -> 77.399687 | I376: =Summary!H7*$N$9 -> 3.3031093
A377: 2010 | B377: 7 | C377: =Summary!E8*$N$3 -> 11.4246 | D377: =Summary!D8*$N$4 -> 12.909748 | E377: =Summary!C8*$N$5 -> 14.538871 | F377: =Summary!I8*$N$6 -> 3.2672818 | G377: =Summary!F8*$N$7 -> 68.205555 | H377: =Summary!G8*$N$8 -> 94.039146 | I377: =Summary!H8*$N$9 -> 3.941093
A378: 2010 | B378: 8 | C378: =Summary!E9*$N$3 -> 6.7518 | D378: =Summary!D9*$N$4 -> 7.953042 | E378: =Summary!C9*$N$5 -> 9.9866252 | F378: =Summary!I9*$N$6 -> 10.901565 | G378: =Summary!F9*$N$7 -> 0.47755125 | H378: =Summary!G9*$N$8 -> 69.200059 | I378: =Summary!H9*$N$9 -> 6.6782489
A379: 2010 | B379: 9 | C379: =Summary!E10*$N$3 -> 5.9895 | D379: =Summary!D10*$N$4 -> 5.1160852 | E379: =Summary!C10*$N$5 -> 11.151913 | F379: =Summary!I10*$N$6 -> 17.595508 | G379: =Summary!F10*$N$7 -> 0 | H379: =Summary!G10*$N$8 -> 64.24316 | I379: =Summary!H10*$N$9 -> 4.1983445
A380: 2010 | B380: 10 | C380: =Summary!E11*$N$3 -> 6.9498 | D380: =Summary!D11*$N$4 -> 7.0605163 | E380: =Summary!C11*$N$5 -> 11.369724 | F380: =Summary!I11*$N$6 -> 11.666587 | G380: =Summary!F11*$N$7 -> 5.9834362 | H380: =Summary!G11*$N$8 -> 68.785164 | I380: =Summary!H11*$N$9 -> 1.3891581
A381: 2010 | B381: 11 | C381: =Summary!E12*$N$3 -> 10.89 | D381: =Summary!D12*$N$4 -> 11.857842 | E381: =Summary!C12*$N$5 -> 17.359521 | F381: =Summary!I12*$N$6 -> 11.921594 | G381: =Summary!F12*$N$7 -> 0.89892 | H381: =Summary!G12*$N$8 -> 91.418758 | I381: =Summary!H12*$N$9 -> 3.0355677
A382: 2010 | B382: 12 | C382: =Summary!E13*$N$3 -> 11.9988 | D382: =Summary!D13*$N$4 -> 13.754459 | E382: =Summary!C13*$N$5 -> 15.867517 | F382: =Summary!I13*$N$6 -> 3.9207382 | G382: =Summary!F13*$N$7 -> 3.3147675 | H382: =Summary!G13*$N$8 -> 93.296703 | I382: =Summary!H13*$N$9 -> 5.2788008
... A5118: 2022 | B5118: 365 | C5118: =Summary!E4749*$N$3 -> 15.4143 | D5118: =Summary!D4749*$N$4 -> 21.835005 | E5118: =Summary!C4749*$N$5 -> 21.225662 | F5118: =Summary!I4749*$N$6 -> 14.806365 | G5118: =Summary!F4749*$N$7 -> 0 | H5118: =Summary!G4749*$N$8 -> 74.899401 | I5118: =Summary!H4749*$N$9 -> 0.98784576
